Workbook
Name a: #REF!
Name a: #REF!
Name a: #REF!
Name AGOSTO: #REF!
Name AGOSTO: #REF!
Name AGOSTO: #REF!
Name d: #REF!
Name d: #REF!
Name d: #REF!
Name DEALER: [1]MAESTRO!$N$3:$N$63
Name DEALER: [1]MAESTRO!$N$3:$N$63
Name DEALER: MAESTRO!$N$3:$N$55
Name DEALER: MAESTRO!$N$3:$N$55
Name febrero: #REF!
Name febrero: #REF!
Name febrero: #REF!
Name JKH: #REF!
Name JKH: #REF!
Name JKH: #REF!
Name JUNIO: #REF!
Name JUNIO: #REF!
Name JUNIO: #REF!
Name ListaMeses: [1]MAESTRO!$H$3:$H$14
Name MES: #REF!
Name MES: #REF!
Name MES: #REF!
Name MES: #REF!
Name MES: #REF!
Name MES: #REF!
Name MES: #REF!
Name MES: #REF!
Name MES: #REF!
Name MES: #REF!
Name MES: #REF!
Name MES: #REF!
Name MES: #REF!
Name MES: #REF!
Name MES: #REF!
Name MES_DASHBOARD: Tabla6[MES]
Name MES_DASHBOARD: Tabla6[MES]
Name MES_DASHBOARD: Tabla6[MES]
Name MES_DASHBOARD: Tabla6[MES]
Name MES_DASHBOARD: Tabla6[MES]
Name MES_DASHBOARD: Tabla6[MES]
Name MES_DASHBOARD: Tabla6[MES]
Name MES_DASHBOARD: Tabla6[MES]
Name PRUEBA: #REF!
Name PRUEBA: #REF!
Name PRUEBA: #REF!
Name PRUEBA: #REF!
Name PRUEBA: #REF!
Name PRUEBA: #REF!
Name PRUEBA: #REF!
Name PRUEBA: #REF!
Name PRUEBA: #REF!
Name PRUEBA: #REF!
Name PRUEBA: #REF!
Name PRUEBA: #REF!
Name PRUEBA: #REF!
Name Q: Tabla7[Q]

Sheet Dealer Dashboard
C3: REPORTE MENSUAL: | F3: Acumulado Mes | G3: JUNIO | I3: =IF(F3="SEMESTRE 1", "ENERO - JUNIO", IF(F3="SEMESTRE 2", "JULIO - DICIEMBRE", "")) | K3: 2026
O4: TRUE
D5: Concesión: | E5: BYMYCAR MADRID
F11: Performance | G11: BMW | I11: MINI
F12: Objetivo Ventas Retail | G12: {=IFERROR( IF(OR(F3="Acumulado Mes", F3="Acumulado Mes 2º S"), SUMPRODUCT( INDEX( 'UC BMW 2026 BPS'!$F$4:$DH$67, MATCH(E5, 'UC BMW 2026 BPS'!$C$4:$C$67, 0), IF( F3="Acumulado Mes 2º S", {37;43;49;55;61;67}, {1;7;13;19;25;31;37;43;49;55;61;67} ) ), IF( F3="Acumulado Mes 2º S", CHOOSE( MATCH($G$3, {"JULIO";"AGOSTO";"SEPTIEMBRE";"OCTUBRE";"NOVIEMBRE";"DICIEMBRE"}, 0), {1;0;0;0;0;0}, {1;1;0;0;0;0}, {1;1;1;0;0;0}, {1;1;1;1;0;0}, {1;1;1;1;1;0}, {1;1;1;1;1;1} ), CHOOSE( MATCH($G$3, {"ENERO";"FEBRERO";"MARZO";"ABRIL";"MAYO";"JUNIO";"JULIO";"AGOSTO";"SEPTIEMBRE";"OCTUBRE";"NOVIEMBRE";"DICIEMBRE"}, 0), {1;0;0;0;0;0;0;0;0;0;0;0}, {1;1;0;0;0;0;0;0;0;0;0;0}, {1;1;1;0;0;0;0;0;0;0;0;0}, {1;1;1;1;0;0;0;0;0;0;0;0}, {1;1;1;1;1;0;0;0;0;0;0;0}, {1;1;1;1;1;1;0;0;0;0;0;0}, {1;1;1;1;1;1;1;0;0;0;0;0}, {1;1;1;1;1;1;1;1;0;0;0;0}, {1;1;1;1;1;1;1;1;1;0;0;0}, {1;1;1;1;1;1;1;1;1;1;0;0}, {1;1;1;1;1;1;1;1;1;1;1;0}, {1;1;1;1;1;1;1;1;1;1;1;1} ) ) ), INDEX( 'UC BMW 2026 BPS'!$F$4:$DH$67, MATCH(E5, 'UC BMW 2026 BPS'!$C$4:$C$67, 0), CHOOSE( MATCH(F3, {"ENERO";"FEBRERO";"MARZO";"ABRIL";"MAYO";"JUNIO";"JULIO";"AGOSTO";"SEPTIEMBRE";"OCTUBRE";"NOVIEMBRE";"DICIEMBRE";"ANUAL";"SEMESTRE 1";"SEMESTRE 2"}, 0), 1, 7, 13, 19, 25, 31, 37, 43, 49, 55, 61, 67, 80, 94, 101 ) ) ), "No encontrado" )} -> 250 | I12: {=IFERROR( IF(OR(F3="Acumulado Mes", F3="Acumulado Mes 2º S"), SUMPRODUCT( INDEX( 'UC MINI 2026 MINI NEXT'!$F$4:$DT$64, MATCH(E5, 'UC MINI 2026 MINI NEXT'!$C$4:$C$63, 0), IF( F3="Acumulado Mes 2º S", {43;50;57;64;71;78}, {1;8;15;22;29;36;43;50;57;64;71;78} ) ), IF( F3="Acumulado Mes 2º S", CHOOSE( MATCH($G$3, {"JULIO";"AGOSTO";"SEPTIEMBRE";"OCTUBRE";"NOVIEMBRE";"DICIEMBRE"}, 0), {1;0;0;0;0;0}, {1;1;0;0;0;0}, {1;1;1;0;0;0}, {1;1;1;1;0;0}, {1;1;1;1;1;0}, {1;1;1;1;1;1} ), CHOOSE( MATCH($G$3, {"ENERO";"FEBRERO";"MARZO";"ABRIL";"MAYO";"JUNIO";"JULIO";"AGOSTO";"SEPTIEMBRE";"OCTUBRE";"NOVIEMBRE";"DICIEMBRE"}, 0), {1;0;0;0;0;0;0;0;0;0;0;0}, {1;1;0;0;0;0;0;0;0;0;0;0}, {1;1;1;0;0;0;0;0;0;0;0;0}, {1;1;1;1;0;0;0;0;0;0;0;0}, {1;1;1;1;1;0;0;0;0;0;0;0}, {1;1;1;1;1;1;0;0;0;0;0;0}, {1;1;1;1;1;1;1;0;0;0;0;0}, {1;1;1;1;1;1;1;1;0;0;0;0}, {1;1;1;1;1;1;1;1;1;0;0;0}, {1;1;1;1;1;1;1;1;1;1;0;0}, {1;1;1;1;1;1;1;1;1;1;1;0}, {1;1;1;1;1;1;1;1;1;1;1;1} ) ) ), INDEX( 'UC MINI 2026 MINI NEXT'!$F$4:$DT$64, MATCH(E5, 'UC MINI 2026 MINI NEXT'!$C$4:$C$63, 0), CHOOSE( MATCH(F3, {"ENERO";"FEBRERO";"MARZO";"ABRIL";"MAYO";"JUNIO";"JULIO";"AGOSTO";"SEPTIEMBRE";"OCTUBRE";"NOVIEMBRE";"DICIEMBRE";"ANUAL";"SEMESTRE 1";"SEMESTRE 2"}, 0), 1, 8, 15, 22, 29, 36, 43, 50, 57, 64, 71, 78, 92, 106, 113 ) ) ), "No encontrado" )} -> 75 | M12: =IFERROR((G13-G12)/G12,0) -> 0.248 | P12: =IFERROR((I13-I12)/I12,0) -> 0.42666667
F13: Realizado Ventas Retail | G13: {=IFERROR( IF(OR(F3="Acumulado Mes", F3="Acumulado Mes 2º S"), SUMPRODUCT( INDEX( 'UC BMW 2026 BPS'!$F$4:$DH$67, MATCH(E5, 'UC BMW 2026 BPS'!$C$4:$C$67, 0), IF( F3="Acumulado Mes 2º S", {38;44;50;56;62;68}, {2;8;14;20;26;32;38;44;50;56;62;68} ) ), IF( F3="Acumulado Mes 2º S", CHOOSE( MATCH($G$3, {"JULIO";"AGOSTO";"SEPTIEMBRE";"OCTUBRE";"NOVIEMBRE";"DICIEMBRE"}, 0), {1;0;0;0;0;0}, {1;1;0;0;0;0}, {1;1;1;0;0;0}, {1;1;1;1;0;0}, {1;1;1;1;1;0}, {1;1;1;1;1;1} ), CHOOSE( MATCH($G$3, {"ENERO";"FEBRERO";"MARZO";"ABRIL";"MAYO";"JUNIO";"JULIO";"AGOSTO";"SEPTIEMBRE";"OCTUBRE";"NOVIEMBRE";"DICIEMBRE"}, 0), {1;0;0;0;0;0;0;0;0;0;0;0}, {1;1;0;0;0;0;0;0;0;0;0;0}, {1;1;1;0;0;0;0;0;0;0;0;0}, {1;1;1;1;0;0;0;0;0;0;0;0}, {1;1;1;1;1;0;0;0;0;0;0;0}, {1;1;1;1;1;1;0;0;0;0;0;0}, {1;1;1;1;1;1;1;0;0;0;0;0}, {1;1;1;1;1;1;1;1;0;0;0;0}, {1;1;1;1;1;1;1;1;1;0;0;0}, {1;1;1;1;1;1;1;1;1;1;0;0}, {1;1;1;1;1;1;1;1;1;1;1;0}, {1;1;1;1;1;1;1;1;1;1;1;1} ) ) ), INDEX( 'UC BMW 2026 BPS'!$F$4:$DH$67, MATCH(E5, 'UC BMW 2026 BPS'!$C$4:$C$67, 0), CHOOSE( MATCH(F3, {"ENERO";"FEBRERO";"MARZO";"ABRIL";"MAYO";"JUNIO";"JULIO";"AGOSTO";"SEPTIEMBRE";"OCTUBRE";"NOVIEMBRE";"DICIEMBRE";"ANUAL";"SEMESTRE 1";"SEMESTRE 2"}, 0), 2, 8, 14, 20, 26, 32, 38, 44, 50, 56, 62, 68, 81, 95, 102 ) ) ), "No encontrado" )} -> 312 | I13: {=IFERROR( IF(OR(F3="Acumulado Mes", F3="Acumulado Mes 2º S"), SUMPRODUCT( INDEX( 'UC MINI 2026 MINI NEXT'!$F$4:$DT$64, MATCH(E5, 'UC MINI 2026 MINI NEXT'!$C$4:$C$63, 0), IF( F3="Acumulado Mes 2º S", {44;51;58;65;72;79}, {2;9;16;23;30;37;44;51;58;65;72;79} ) ), IF( F3="Acumulado Mes 2º S", CHOOSE( MATCH($G$3, {"JULIO";"AGOSTO";"SEPTIEMBRE";"OCTUBRE";"NOVIEMBRE";"DICIEMBRE"}, 0), {1;0;0;0;0;0}, {1;1;0;0;0;0}, {1;1;1;0;0;0}, {1;1;1;1;0;0}, {1;1;1;1;1;0}, {1;1;1;1;1;1} ), CHOOSE( MATCH($G$3, {"ENERO";"FEBRERO";"MARZO";"ABRIL";"MAYO";"JUNIO";"JULIO";"AGOSTO";"SEPTIEMBRE";"OCTUBRE";"NOVIEMBRE";"DICIEMBRE"}, 0), {1;0;0;0;0;0;0;0;0;0;0;0}, {1;1;0;0;0;0;0;0;0;0;0;0}, {1;1;1;0;0;0;0;0;0;0;0;0}, {1;1;1;1;0;0;0;0;0;0;0;0}, {1;1;1;1;1;0;0;0;0;0;0;0}, {1;1;1;1;1;1;0;0;0;0;0;0}, {1;1;1;1;1;1;1;0;0;0;0;0}, {1;1;1;1;1;1;1;1;0;0;0;0}, {1;1;1;1;1;1;1;1;1;0;0;0}, {1;1;1;1;1;1;1;1;1;1;0;0}, {1;1;1;1;1;1;1;1;1;1;1;0}, {1;1;1;1;1;1;1;1;1;1;1;1} ) ) ), INDEX( 'UC MINI 2026 MINI NEXT'!$F$4:$DT$64, MATCH(E5, 'UC MINI 2026 MINI NEXT'!$C$4:$C$63, 0), CHOOSE( MATCH(F3, {"ENERO";"FEBRERO";"MARZO";"ABRIL";"MAYO";"JUNIO";"JULIO";"AGOSTO";"SEPTIEMBRE";"OCTUBRE";"NOVIEMBRE";"DICIEMBRE";"ANUAL";"SEMESTRE 1";"SEMESTRE 2"}, 0), 2, 9, 16, 23, 30, 37, 44, 51, 58, 65, 72, 79, 93, 107, 114 ) ) ), "No encontrado" )} -> 107
F14: % Cumplimentación Ventas Retail | G14: =IFERROR(G13/G12,0) -> 1.248 | I14: =IFERROR(I13/I12,0) -> 1.4266667
F15: Ventas BPS / MN | G15: {=IFERROR( IF(OR(F3="Acumulado Mes", F3="Acumulado Mes 2º S"), SUMPRODUCT( INDEX( 'UC BMW 2026 BPS'!$F$4:$DH$67, MATCH(E5, 'UC BMW 2026 BPS'!$C$4:$C$67, 0), IF( F3="Acumulado Mes 2º S", {39;45;51;57;63;69}, {3;9;15;21;27;33;39;45;51;57;63;69} ) ), IF( F3="Acumulado Mes 2º S", CHOOSE( MATCH($G$3, {"JULIO";"AGOSTO";"SEPTIEMBRE";"OCTUBRE";"NOVIEMBRE";"DICIEMBRE"}, 0), {1;0;0;0;0;0}, {1;1;0;0;0;0}, {1;1;1;0;0;0}, {1;1;1;1;0;0}, {1;1;1;1;1;0}, {1;1;1;1;1;1} ), CHOOSE( MATCH($G$3, {"ENERO";"FEBRERO";"MARZO";"ABRIL";"MAYO";"JUNIO";"JULIO";"AGOSTO";"SEPTIEMBRE";"OCTUBRE";"NOVIEMBRE";"DICIEMBRE"}, 0), {1;0;0;0;0;0;0;0;0;0;0;0}, {1;1;0;0;0;0;0;0;0;0;0;0}, {1;1;1;0;0;0;0;0;0;0;0;0}, {1;1;1;1;0;0;0;0;0;0;0;0}, {1;1;1;1;1;0;0;0;0;0;0;0}, {1;1;1;1;1;1;0;0;0;0;0;0}, {1;1;1;1;1;1;1;0;0;0;0;0}, {1;1;1;1;1;1;1;1;0;0;0;0}, {1;1;1;1;1;1;1;1;1;0;0;0}, {1;1;1;1;1;1;1;1;1;1;0;0}, {1;1;1;1;1;1;1;1;1;1;1;0}, {1;1;1;1;1;1;1;1;1;1;1;1} ) ) ), INDEX( 'UC BMW 2026 BPS'!$F$4:$DH$67, MATCH(E5, 'UC BMW 2026 BPS'!$C$4:$C$67, 0), CHOOSE( MATCH(F3, {"ENERO";"FEBRERO";"MARZO";"ABRIL";"MAYO";"JUNIO";"JULIO";"AGOSTO";"SEPTIEMBRE";"OCTUBRE";"NOVIEMBRE";"DICIEMBRE";"ANUAL";"SEMESTRE 1";"SEMESTRE 2"}, 0), 3, 9, 15, 21, 27, 33, 39, 45, 51, 57, 63, 69, 83, 97, 104 ) ) ), "No encontrado" )} -> 288 | I15: {=IFERROR( IF(OR(F3="Acumulado Mes", F3="Acumulado Mes 2º S"), SUMPRODUCT( INDEX( 'UC MINI 2026 MINI NEXT'!$F$4:$DT$64, MATCH(E5, 'UC MINI 2026 MINI NEXT'!$C$4:$C$63, 0), IF( F3="Acumulado Mes 2º S", {46;53;60;67;74;81}, {4;11;18;25;32;39;46;53;60;67;74;81} ) ), IF( F3="Acumulado Mes 2º S", CHOOSE( MATCH($G$3, {"JULIO";"AGOSTO";"SEPTIEMBRE";"OCTUBRE";"NOVIEMBRE";"DICIEMBRE"}, 0), {1;0;0;0;0;0}, {1;1;0;0;0;0}, {1;1;1;0;0;0}, {1;1;1;1;0;0}, {1;1;1;1;1;0}, {1;1;1;1;1;1} ), CHOOSE( MATCH($G$3, {"ENERO";"FEBRERO";"MARZO";"ABRIL";"MAYO";"JUNIO";"JULIO";"AGOSTO";"SEPTIEMBRE";"OCTUBRE";"NOVIEMBRE";"DICIEMBRE"}, 0), {1;0;0;0;0;0;0;0;0;0;0;0}, {1;1;0;0;0;0;0;0;0;0;0;0}, {1;1;1;0;0;0;0;0;0;0;0;0}, {1;1;1;1;0;0;0;0;0;0;0;0}, {1;1;1;1;1;0;0;0;0;0;0;0}, {1;1;1;1;1;1;0;0;0;0;0;0}, {1;1;1;1;1;1;1;0;0;0;0;0}, {1;1;1;1;1;1;1;1;0;0;0;0}, {1;1;1;1;1;1;1;1;1;0;0;0}, {1;1;1;1;1;1;1;1;1;1;0;0}, {1;1;1;1;1;1;1;1;1;1;1;0}, {1;1;1;1;1;1;1;1;1;1;1;1} ) ) ), INDEX( 'UC MINI 2026 MINI NEXT'!$F$4:$DT$64, MATCH(E5, 'UC MINI 2026 MINI NEXT'!$C$4:$C$63, 0), CHOOSE( MATCH(F3, {"ENERO";"FEBRERO";"MARZO";"ABRIL";"MAYO";"JUNIO";"JULIO";"AGOSTO";"SEPTIEMBRE";"OCTUBRE";"NOVIEMBRE";"DICIEMBRE";"ANUAL";"SEMESTRE 1";"SEMESTRE 2"}, 0), 4, 11, 18, 25, 32, 39, 46, 53, 60, 67, 74, 81, 95, 109, 116 ) ) ), "No encontrado" )} -> 98
F16: % BPS / % MN | G16: =IFERROR(G15/G13,0) -> 0.92307692 | I16: =IFERROR(I15/I13,0) -> 0.91588785
F17: Retail Origen Remarketing | G17: {=IFERROR( IF(OR(F3="Acumulado Mes", F3="Acumulado Mes 2º S"), SUMPRODUCT( INDEX( 'UC BMW 2026 BPS'!$F$4:$DH$67, MATCH(E5, 'UC BMW 2026 BPS'!$C$4:$C$67, 0), IF( F3="Acumulado Mes 2º S", {41;47;53;59;65;71}, {5;11;17;23;29;35;41;47;53;59;65;71} ) ), IF( F3="Acumulado Mes 2º S", CHOOSE( MATCH($G$3, {"JULIO";"AGOSTO";"SEPTIEMBRE";"OCTUBRE";"NOVIEMBRE";"DICIEMBRE"}, 0), {1;0;0;0;0;0}, {1;1;0;0;0;0}, {1;1;1;0;0;0}, {1;1;1;1;0;0}, {1;1;1;1;1;0}, {1;1;1;1;1;1} ), CHOOSE( MATCH($G$3, {"ENERO";"FEBRERO";"MARZO";"ABRIL";"MAYO";"JUNIO";"JULIO";"AGOSTO";"SEPTIEMBRE";"OCTUBRE";"NOVIEMBRE";"DICIEMBRE"}, 0), {1;0;0;0;0;0;0;0;0;0;0;0}, {1;1;0;0;0;0;0;0;0;0;0;0}, {1;1;1;0;0;0;0;0;0;0;0;0}, {1;1;1;1;0;0;0;0;0;0;0;0}, {1;1;1;1;1;0;0;0;0;0;0;0}, {1;1;1;1;1;1;0;0;0;0;0;0}, {1;1;1;1;1;1;1;0;0;0;0;0}, {1;1;1;1;1;1;1;1;0;0;0;0}, {1;1;1;1;1;1;1;1;1;0;0;0}, {1;1;1;1;1;1;1;1;1;1;0;0}, {1;1;1;1;1;1;1;1;1;1;1;0}, {1;1;1;1;1;1;1;1;1;1;1;1} ) ) ), INDEX( 'UC BMW 2026 BPS'!$F$4:$DH$67, MATCH(E5, 'UC BMW 2026 BPS'!$C$4:$C$67, 0), CHOOSE( MATCH(F3, {"ENERO";"FEBRERO";"MARZO";"ABRIL";"MAYO";"JUNIO";"JULIO";"AGOSTO";"SEPTIEMBRE";"OCTUBRE";"NOVIEMBRE";"DICIEMBRE";"ANUAL";"SEMESTRE 1";"SEMESTRE 2"}, 0), 5, 11, 17, 23, 29, 35, 41, 47, 53, 59, 65, 71, 85, 99, 106 ) ) ), "No encontrado" )} -> 67 | I17: {=IFERROR( IF(OR(F3="Acumulado Mes", F3="Acumulado Mes 2º S"), SUMPRODUCT( INDEX( 'UC MINI 2026 MINI NEXT'!$F$4:$DT$64, MATCH(E5, 'UC MINI 2026 MINI NEXT'!$C$4:$C$63, 0), IF( F3="Acumulado Mes 2º S", {48;55;62;69;76;83}, {6;13;20;27;34;41;48;55;62;69;76;83} ) ), IF( F3="Acumulado Mes 2º S", CHOOSE( MATCH($G$3, {"JULIO";"AGOSTO";"SEPTIEMBRE";"OCTUBRE";"NOVIEMBRE";"DICIEMBRE"}, 0), {1;0;0;0;0;0}, {1;1;0;0;0;0}, {1;1;1;0;0;0}, {1;1;1;1;0;0}, {1;1;1;1;1;0}, {1;1;1;1;1;1} ), CHOOSE( MATCH($G$3, {"ENERO";"FEBRERO";"MARZO";"ABRIL";"MAYO";"JUNIO";"JULIO";"AGOSTO";"SEPTIEMBRE";"OCTUBRE";"NOVIEMBRE";"DICIEMBRE"}, 0), {1;0;0;0;0;0;0;0;0;0;0;0}, {1;1;0;0;0;0;0;0;0;0;0;0}, {1;1;1;0;0;0;0;0;0;0;0;0}, {1;1;1;1;0;0;0;0;0;0;0;0}, {1;1;1;1;1;0;0;0;0;0;0;0}, {1;1;1;1;1;1;0;0;0;0;0;0}, {1;1;1;1;1;1;1;0;0;0;0;0}, {1;1;1;1;1;1;1;1;0;0;0;0}, {1;1;1;1;1;1;1;1;1;0;0;0}, {1;1;1;1;1;1;1;1;1;1;0;0}, {1;1;1;1;1;1;1;1;1;1;1;0}, {1;1;1;1;1;1;1;1;1;1;1;1} ) ) ), INDEX( 'UC MINI 2026 MINI NEXT'!$F$4:$DT$64, MATCH(E5, 'UC MINI 2026 MINI NEXT'!$C$4:$C$63, 0), CHOOSE( MATCH(F3, {"ENERO";"FEBRERO";"MARZO";"ABRIL";"MAYO";"JUNIO";"JULIO";"AGOSTO";"SEPTIEMBRE";"OCTUBRE";"NOVIEMBRE";"DICIEMBRE";"ANUAL";"SEMESTRE 1";"SEMESTRE 2"}, 0), 6, 13, 20, 27, 34, 41, 48, 55, 62, 69, 76, 83, 97, 111, 118 ) ) ), "No encontrado" )} -> 27
F18: % Retail Origen Remarketing | G18: =IFERROR(G17/G12,0) -> 0.268 | I18: =IFERROR(I17/I12,0) -> 0.36
F19: Ventas Totales BEV | G19: {=IFERROR( IF(OR(F3="Acumulado Mes", F3="Acumulado Mes 2º S"), SUMPRODUCT( INDEX( 'BEV BMW 2026'!$F$4:$BH$67, MATCH(E5, 'BEV BMW 2026'!$C$4:$C$67, 0), IF( F3="Acumulado Mes 2º S", {20;23;26;29;32;35}, {2;5;8;11;14;17;20;23;26;29;32;35} ) ), IF( F3="Acumulado Mes 2º S", CHOOSE( MATCH(G3, {"JULIO";"AGOSTO";"SEPTIEMBRE";"OCTUBRE";"NOVIEMBRE";"DICIEMBRE"}, 0), {1;0;0;0;0;0}, {1;1;0;0;0;0}, {1;1;1;0;0;0}, {1;1;1;1;0;0}, {1;1;1;1;1;0}, {1;1;1;1;1;1} ), CHOOSE( MATCH(G3, {"ENERO";"FEBRERO";"MARZO";"ABRIL";"MAYO";"JUNIO";"JULIO";"AGOSTO";"SEPTIEMBRE";"OCTUBRE";"NOVIEMBRE";"DICIEMBRE"}, 0), {1;0;0;0;0;0;0;0;0;0;0;0}, {1;1;0;0;0;0;0;0;0;0;0;0}, {1;1;1;0;0;0;0;0;0;0;0;0}, {1;1;1;1;0;0;0;0;0;0;0;0}, {1;1;1;1;1;0;0;0;0;0;0;0}, {1;1;1;1;1;1;0;0;0;0;0;0}, {1;1;1;1;1;1;1;0;0;0;0;0}, {1;1;1;1;1;1;1;1;0;0;0;0}, {1;1;1;1;1;1;1;1;1;0;0;0}, {1;1;1;1;1;1;1;1;1;1;0;0}, {1;1;1;1;1;1;1;1;1;1;1;0}, {1;1;1;1;1;1;1;1;1;1;1;1} ) ) ), INDEX( 'BEV BMW 2026'!$F$4:$BH$67, MATCH(E5, 'BEV BMW 2026'!$C$4:$C$67, 0), CHOOSE( MATCH(F3, {"ENERO";"FEBRERO";"MARZO";"ABRIL";"MAYO";"JUNIO";"JULIO";"AGOSTO";"SEPTIEMBRE";"OCTUBRE";"NOVIEMBRE";"DICIEMBRE";"ANUAL";"SEMESTRE 1";"SEMESTRE 2"}, 0), 2, 5, 8, 11, 14, 17, 20, 23, 26, 29, 32, 35, 41, 51, 54 ) ) ), "No encontrado" )} -> 701 | I19: {=IFERROR( IF(OR(F3="Acumulado Mes", F3="Acumulado Mes 2º S"), SUMPRODUCT( INDEX( 'BEV MINI 2026'!$F$4:$BH$64, MATCH(E5, 'BEV MINI 2026'!$C$4:$C$64, 0), IF( F3="Acumulado Mes 2º S", {20;23;26;29;32;35}, {2;5;8;11;14;17;20;23;26;29;32;35} ) ), IF( F3="Acumulado Mes 2º S", CHOOSE( MATCH($G$3, {"JULIO";"AGOSTO";"SEPTIEMBRE";"OCTUBRE";"NOVIEMBRE";"DICIEMBRE"}, 0), {1;0;0;0;0;0}, {1;1;0;0;0;0}, {1;1;1;0;0;0}, {1;1;1;1;0;0}, {1;1;1;1;1;0}, {1;1;1;1;1;1} ), CHOOSE( MATCH($G$3, {"ENERO";"FEBRERO";"MARZO";"ABRIL";"MAYO";"JUNIO";"JULIO";"AGOSTO";"SEPTIEMBRE";"OCTUBRE";"NOVIEMBRE";"DICIEMBRE"}, 0), {1;0;0;0;0;0;0;0;0;0;0;0}, {1;1;0;0;0;0;0;0;0;0;0;0}, {1;1;1;0;0;0;0;0;0;0;0;0}, {1;1;1;1;0;0;0;0;0;0;0;0}, {1;1;1;1;1;0;0;0;0;0;0;0}, {1;1;1;1;1;1;0;0;0;0;0;0}, {1;1;1;1;1;1;1;0;0;0;0;0}, {1;1;1;1;1;1;1;1;0;0;0;0}, {1;1;1;1;1;1;1;1;1;0;0;0}, {1;1;1;1;1;1;1;1;1;1;0;0}, {1;1;1;1;1;1;1;1;1;1;1;0}, {1;1;1;1;1;1;1;1;1;1;1;1} ) ) ), INDEX( 'BEV MINI 2026'!$F$4:$BH$64, MATCH(E5, 'BEV MINI 2026'!$C$4:$C$64, 0), CHOOSE( MATCH(F3, {"ENERO";"FEBRERO";"MARZO";"ABRIL";"MAYO";"JUNIO";"JULIO";"AGOSTO";"SEPTIEMBRE";"OCTUBRE";"NOVIEMBRE";"DICIEMBRE";"ANUAL";"SEMESTRE 1";"SEMESTRE 2"}, 0), 2, 5, 8, 11, 14, 17, 20, 23, 26, 29, 32, 35, 41, 51, 54 ) ) ), "No encontrado" )} -> 162
F20: % de Ventas Totales BEV | G20: =IFERROR(G19/G12,0) -> 2.804 | I20: =IFERROR(I19/I12,0) -> 2.16
F22: Mystery Shopping VO | G22: =IFERROR(IF(OR(F3="ENERO",F3="FEBRERO",F3="MARZO",F3="ABRIL",F3="MAYO",F3="JUNIO"), INDEX('MYS 2026'!$F$5:$F$68,MATCH(E5,'MYS 2026'!$C$5:$C$68,0)), IF(OR(F3="JULIO",F3="AGOSTO",F3="SEPTIEMBRE",F3="OCTUBRE",F3="NOVIEMBRE",F3="DICIEMBRE"), INDEX('MYS 2026'!$H$5:$H$68,MATCH(E5,'MYS 2026'!$C$5:$C$68,0)), IF(F3="ANUAL", 0, IF(F3="SEMESTRE 1", INDEX('MYS 2026'!$F$5:$F$68,MATCH(E5,'MYS 2026'!$C$5:$C$68,0)), IF(F3="SEMESTRE 2", INDEX('MYS 2026'!$H$5:$H$68,MATCH(E5,'MYS 2026'!$C$5:$C$68,0)), IF(F3="ACUMULADO MES", IF(OR(G3="ENERO",G3="FEBRERO",G3="MARZO",G3="ABRIL",G3="MAYO",G3="JUNIO"), INDEX('MYS 2026'!$F$5:$F$68,MATCH(E5,'MYS 2026'!$C$5:$C$68,0)), INDEX('MYS 2026'!$H$5:$H$68,MATCH(E5,'MYS 2026'!$C$5:$C$68,0))), "")))))), "") -> 0.79 | I22: =IFERROR(IF(OR(F3="ENERO",F3="FEBRERO",F3="MARZO",F3="ABRIL",F3="MAYO",F3="JUNIO"), INDEX('MYS 2026'!$G$5:$G$68,MATCH(E5,'MYS 2026'!$C$5:$C$68,0)), IF(OR(F3="JULIO",F3="AGOSTO",F3="SEPTIEMBRE",F3="OCTUBRE",F3="NOVIEMBRE",F3="DICIEMBRE"), INDEX('MYS 2026'!$I$5:$I$68,MATCH(E5,'MYS 2026'!$C$5:$C$68,0)), IF(F3="ANUAL", 0, IF(F3="SEMESTRE 1", INDEX('MYS 2026'!$G$5:$G$68,MATCH(E5,'MYS 2026'!$C$5:$C$68,0)), IF(F3="SEMESTRE 2", INDEX('MYS 2026'!$I$5:$I$68,MATCH(E5,'MYS 2026'!$C$5:$C$68,0)), IF(F3="ACUMULADO MES", IF(OR(G3="ENERO",G3="FEBRERO",G3="MARZO",G3="ABRIL",G3="MAYO",G3="JUNIO"), INDEX('MYS 2026'!$G$5:$G$68,MATCH(E5,'MYS 2026'!$C$5:$C$68,0)), INDEX('MYS 2026'!$I$5:$I$68,MATCH(E5,'MYS 2026'!$C$5:$C$68,0))), "")))))), "") -> 1
F24: Ventas BPS / MN Necesarias para alcanzar penetración | G24: =IFERROR(IF(OR(G15=0, ISBLANK(G15)), 4 * G13, MAX(0, 4 * (G13 - 1.25 * G15))),0) -> 0 | I24: =IFERROR(IF(OR(I15=0, ISBLANK(I15)), 4 * I13, MAX(0, 4 * (I13 - 1.25 * I15))),0) -> 0
G26: 18% ≤ x < 22% | H26: 22% ≤ x < 27% | I26: 27% ≤ x < 32% | J26: x ≥ 32%
F27: Ventas Origen Remarkting necesarias para alcanzar porcentaje | G27: =IFERROR( IF( (G17 / G12) >= 0.18, 0, ROUNDUP((0.18 * G12 - G17) / (1 - 0.18), 0) ), 0 ) -> 0 | H27: =IFERROR(IF(OR(G12<=0, G17/G12>=0.22), 0, ROUNDUP(0.22*G12-G17, 0)), 0) -> 0 | I27: =IFERROR(IF(OR(G12<=0, G17/G12>=0.27), 0, ROUNDUP(0.27*G12-G17, 0)), 0) -> 1 | J27: =IFERROR(IF(OR(G12<=0, G17/G12>=0.32), 0, ROUNDUP(0.32*G12-G17, 0)), 0) -> 13
G28: 15% ≤ x < 20% | H28: 20% ≤ x < 25% | I28: 25% ≤ x < 30% | J28: x ≥ 30%
G29: 15% ≤ x < 20% | H29: 20% ≤ x < 25% | I29: 25% ≤ x < 30% | J29: x ≥ 30%
G30: =IFERROR(IF(OR(I12<=0, I17/I12>=0.15), 0, ROUNDUP(0.15*I12-I17, 0)), 0) -> 0 | H30: =IFERROR(IF(OR(I12<=0, I17/I12>=0.2), 0, ROUNDUP(0.2*I12-I17, 0)), 0) -> 0 | I30: =IFERROR(IF(OR(I12<=0, I17/I12>=0.25), 0, ROUNDUP(0.25*I12-I17, 0)), 0) -> 0 | J30: =IFERROR(IF(OR(I12<=0, I17/I12>=0.3), 0, ROUNDUP(0.3*I12-I17, 0)), 0) -> 0
F32: Ventas BEV Necesarias para alcanzar acelerador | G32: 6% ≤ x < 11% | H32: x ≥ 11% | I32: 10% ≤ x < 15% | J32: x ≥ 15%
G33: =IFERROR( IF((G19 /G12) >= 0.06, 0, ROUNDUP((0.05 *G12 - G19) / (1 - 0.06), 0) ), 0 ) -> 0 | H33: =IFERROR( IF((G19 /G12) >= 0.11, 0, ROUNDUP((0.1 *G12 - G19) / (1 - 0.11), 0) ), 0 ) -> 0 | I33: =IFERROR( IF((I19 /I12) >= 0.1, 0, ROUNDUP((0.05 *I12 - I19) / (1 - 0.1), 0) ), 0 ) -> 0 | J33: =IFERROR( IF((I19 /I12) >= 0.15, 0, ROUNDUP((0.1 *I12 - I19) / (1 - 0.15), 0) ), 0 ) -> 0
F35: =IF(O4=TRUE,"","Mercado <6 años") | G35: {=IF(O4=TRUE,"",IFERROR(IF(OR(F3="Acumulado Mes", F3="Acumulado Mes 2º S"), SUMPRODUCT(INDEX('PENETRACION MERCADO VO BMW'!$F$4:$BH$67, MATCH(E5, 'PENETRACION MERCADO VO BMW'!$C$4:$C$67, 0), IF(F3="Acumulado Mes 2º S", {20;23;26;29;32;35}-1, {2;5;8;11;14;17;20;23;26;29;32;35}-1)), IF(F3="Acumulado Mes 2º S", CHOOSE(MATCH(G3, {"JULIO";"AGOSTO";"SEPTIEMBRE";"OCTUBRE";"NOVIEMBRE";"DICIEMBRE"}, 0), {1;0;0;0;0;0}, {1;1;0;0;0;0}, {1;1;1;0;0;0}, {1;1;1;1;0;0}, {1;1;1;1;1;0}, {1;1;1;1;1;1}), CHOOSE(MATCH(G3, {"ENERO";"FEBRERO";"MARZO";"ABRIL";"MAYO";"JUNIO";"JULIO";"AGOSTO";"SEPTIEMBRE";"OCTUBRE";"NOVIEMBRE";"DICIEMBRE"}, 0), {1;0;0;0;0;0;0;0;0;0;0;0}, {1;1;0;0;0;0;0;0;0;0;0;0}, {1;1;1;0;0;0;0;0;0;0;0;0}, {1;1;1;1;0;0;0;0;0;0;0;0}, {1;1;1;1;1;0;0;0;0;0;0;0}, {1;1;1;1;1;1;0;0;0;0;0;0}, {1;1;1;1;1;1;1;0;0;0;0;0}, {1;1;1;1;1;1;1;1;0;0;0;0}, {1;1;1;1;1;1;1;1;1;0;0;0}, {1;1;1;1;1;1;1;1;1;1;0;0}, {1;1;1;1;1;1;1;1;1;1;1;0}, {1;1;1;1;1;1;1;1;1;1;1;1}))), INDEX('PENETRACION MERCADO VO BMW'!$F$4:$BH$67, MATCH(E5, 'PENETRACION MERCADO VO BMW'!$C$4:$C$67, 0), CHOOSE(MATCH(F3, {"ENERO";"FEBRERO";"MARZO";"ABRIL";"MAYO";"JUNIO";"JULIO";"AGOSTO";"SEPTIEMBRE";"OCTUBRE";"NOVIEMBRE";"DICIEMBRE";"ANUAL";"SEMESTRE 1";"SEMESTRE 2"}, 0), 2,5,8,11,14,17,20,23,26,29,32,35,41,51,54)-1)), "No encontrado"))} | I35: {=IF(O4=TRUE,"",IFERROR(IF(OR(F3="Acumulado Mes", F3="Acumulado Mes 2º S"), SUMPRODUCT(INDEX('PENETRACION MCDO VO MINI'!$F$4:$BH$64, MATCH(E5, 'PENETRACION MCDO VO MINI'!$C$4:$C$64, 0), IF(F3="Acumulado Mes 2º S", {20;23;26;29;32;35}-1, {2;5;8;11;14;17;20;23;26;29;32;35}-1)), IF(F3="Acumulado Mes 2º S", CHOOSE(MATCH($G$3, {"JULIO";"AGOSTO";"SEPTIEMBRE";"OCTUBRE";"NOVIEMBRE";"DICIEMBRE"}, 0), {1;0;0;0;0;0}, {1;1;0;0;0;0}, {1;1;1;0;0;0}, {1;1;1;1;0;0}, {1;1;1;1;1;0}, {1;1;1;1;1;1}), CHOOSE(MATCH($G$3, {"ENERO";"FEBRERO";"MARZO";"ABRIL";"MAYO";"JUNIO";"JULIO";"AGOSTO";"SEPTIEMBRE";"OCTUBRE";"NOVIEMBRE";"DICIEMBRE"}, 0), {1;0;0;0;0;0;0;0;0;0;0;0}, {1;1;0;0;0;0;0;0;0;0;0;0}, {1;1;1;0;0;0;0;0;0;0;0;0}, {1;1;1;1;0;0;0;0;0;0;0;0}, {1;1;1;1;1;0;0;0;0;0;0;0}, {1;1;1;1;1;1;0;0;0;0;0;0}, {1;1;1;1;1;1;1;0;0;0;0;0}, {1;1;1;1;1;1;1;1;0;0;0;0}, {1;1;1;1;1;1;1;1;1;0;0;0}, {1;1;1;1;1;1;1;1;1;1;0;0}, {1;1;1;1;1;1;1;1;1;1;1;0}, {1;1;1;1;1;1;1;1;1;1;1;1}))), INDEX('PENETRACION MCDO VO MINI'!$F$4:$BH$64, MATCH(E5, 'PENETRACION MCDO VO MINI'!$C$4:$C$64, 0), CHOOSE(MATCH(F3, {"ENERO";"FEBRERO";"MARZO";"ABRIL";"MAYO";"JUNIO";"JULIO";"AGOSTO";"SEPTIEMBRE";"OCTUBRE";"NOVIEMBRE";"DICIEMBRE";"ANUAL";"SEMESTRE 1";"SEMESTRE 2"}, 0), 2,5,8,11,14,17,20,23,26,29,32,35,41,51,54)-1)), "No encontrado"))} | L35: =IF(E5="BYMYCAR MADRID","BYMYCAR DIRECTO","") -> BYMYCAR DIRECTO | N35: {=IF(E5<>"BYMYCAR MADRID","", IFERROR(IF(OR(F3="Acumulado Mes", F3="Acumulado Mes 2º S"), SUMPRODUCT(INDEX('UC BMW 2026 BPS'!$F$69:$DH$69, 1, IF(F3="Acumulado Mes 2º S", {38,44,50,56,62,68}, {2,8,14,20,26,32,38,44,50,56,62,68})), IF(F3="Acumulado Mes 2º S", CHOOSE(MATCH($G$3, {"JULIO";"AGOSTO";"SEPTIEMBRE";"OCTUBRE";"NOVIEMBRE";"DICIEMBRE"}, 0), {1,0,0,0,0,0}, {1,1,0,0,0,0}, {1,1,1,0,0,0}, {1,1,1,1,0,0}, {1,1,1,1,1,0}, {1,1,1,1,1,1}), CHOOSE(MATCH($G$3, {"ENERO";"FEBRERO";"MARZO";"ABRIL";"MAYO";"JUNIO";"JULIO";"AGOSTO";"SEPTIEMBRE";"OCTUBRE";"NOVIEMBRE";"DICIEMBRE"}, 0), {1,0,0,0,0,0,0,0,0,0,0,0}, {1,1,0,0,0,0,0,0,0,0,0,0}, {1,1,1,0,0,0,0,0,0,0,0,0}, {1,1,1,1,0,0,0,0,0,0,0,0}, {1,1,1,1,1,0,0,0,0,0,0,0}, {1,1,1,1,1,1,0,0,0,0,0,0}, {1,1,1,1,1,1,1,0,0,0,0,0}, {1,1,1,1,1,1,1,1,0,0,0,0}, {1,1,1,1,1,1,1,1,1,0,0,0}, {1,1,1,1,1,1,1,1,1,1,0,0}, {1,1,1,1,1,1,1,1,1,1,1,0}, {1,1,1,1,1,1,1,1,1,1,1,1}))), INDEX('UC BMW 2026 BPS'!$F$69:$DH$69, 1, CHOOSE(MATCH(F3, {"ENERO";"FEBRERO";"MARZO";"ABRIL";"MAYO";"JUNIO";"JULIO";"AGOSTO";"SEPTIEMBRE";"OCTUBRE";"NOVIEMBRE";"DICIEMBRE";"ANUAL";"SEMESTRE 1";"SEMESTRE 2"}, 0), 2, 8, 14, 20, 26, 32, 38, 44, 50, 56, 62, 68, 81, 95, 102))), "No encontrado"))} -> 139 | O35: {=IF(E5<>"BYMYCAR MADRID","", IFERROR(IF(OR(F3="Acumulado Mes", F3="Acumulado Mes 2º S"), SUMPRODUCT(INDEX('UC MINI 2026 MINI NEXT'!$F$65:$DT$65, 1, IF(F3="Acumulado Mes 2º S", {44,51,58,65,72,79}, {2,9,16,23,30,37,44,51,58,65,72,79})), IF(F3="Acumulado Mes 2º S", CHOOSE(MATCH($G$3, {"JULIO";"AGOSTO";"SEPTIEMBRE";"OCTUBRE";"NOVIEMBRE";"DICIEMBRE"}, 0), {1,0,0,0,0,0}, {1,1,0,0,0,0}, {1,1,1,0,0,0}, {1,1,1,1,0,0}, {1,1,1,1,1,0}, {1,1,1,1,1,1}), CHOOSE(MATCH($G$3, {"ENERO";"FEBRERO";"MARZO";"ABRIL";"MAYO";"JUNIO";"JULIO";"AGOSTO";"SEPTIEMBRE";"OCTUBRE";"NOVIEMBRE";"DICIEMBRE"}, 0), {1,0,0,0,0,0,0,0,0,0,0,0}, {1,1,0,0,0,0,0,0,0,0,0,0}, {1,1,1,0,0,0,0,0,0,0,0,0}, {1,1,1,1,0,0,0,0,0,0,0,0}, {1,1,1,1,1,0,0,0,0,0,0,0}, {1,1,1,1,1,1,0,0,0,0,0,0}, {1,1,1,1,1,1,1,0,0,0,0,0}, {1,1,1,1,1,1,1,1,0,0,0,0}, {1,1,1,1,1,1,1,1,1,0,0,0}, {1,1,1,1,1,1,1,1,1,1,0,0}, {1,1,1,1,1,1,1,1,1,1,1,0}, {1,1,1,1,1,1,1,1,1,1,1,1}))), INDEX('UC MINI 2026 MINI NEXT'!$F$65:$DT$65, 1, CHOOSE(MATCH(F3, {"ENERO";"FEBRERO";"MARZO";"ABRIL";"MAYO";"JUNIO";"JULIO";"AGOSTO";"SEPTIEMBRE";"OCTUBRE";"NOVIEMBRE";"DICIEMBRE";"ANUAL";"SEMESTRE 1";"SEMESTRE 2"}, 0), 2, 9, 16, 23, 30, 37, 44, 51, 58, 65, 72, 79, 93, 107, 114))), "No encontrado"))} -> 36
F36: =IF(O4=TRUE,"","% Penetracion") | G36: =IF(O4=TRUE,"",G13/G35) | I36: =IF(O4=TRUE,"",I13/I35)
F37: =IF(O4=TRUE,"","% Penetracion TOP 10") | G37: {=IF(O4=TRUE,"",'PENETRACION MERCADO VO BMW'!BR31:BR31)} | I37: =IF(O4=TRUE,"",'PENETRACION MCDO VO MINI'!BS32)
G49: =IFERROR((G13-G12)/G12,0) -> 0.248
F50: Variacion % Objetivo vs Realizado BMW | G50: =IFERROR((I13-I12)/I12,0) -> 0.42666667
F51: Variacion % Objetivo vs Realizado MINI
D52: =+B52 -> 0
D53: =+B53 -> 0
D54: =+B54 -> 0
D55: =+B55 -> 0
D56: =+B56 -> 0
D57: =+B57 -> 0
D58: =+B58 -> 0
D59: =+B59 -> 0
D60: =+B60 -> 0
D61: =+B61 -> 0
D62: =+B62 -> 0
D63: =+B63 -> 0
...

Sheet UC BMW 2026
A1: S E G U I M I E N T O UC R E T A I L B M W 2 0 2 6
A2: «' | F2: 8 | H2: 10 | J2: 12 | L2: 16 | N2: 18 | P2: 20 | R2: 24 | T2: 26 | V2: 28 | X2: 32 | Z2: 34 | AB2: 36 | AD2: JUNIO
B3: NUM. | C3: CONCESIONARIO | D3: GRUPO PROPIETARIO | F3: ENERO | H3: FEBRERO | J3: MARZO | L3: ABRIL | N3: MAYO | P3: JUNIO | R3: JULIO | T3: AGOSTO | V3: SEPT. | X3: OCTU | Z3: NOVBRE | AB3: DICIEM. | AD3: ACUMULADO MES | AG3: ACUM. ANUAL | AJ3: Q1 | AM3: S 2
F4: OBJ | G4: RE | H4: OBJ | I4: RE | J4: OBJ | K4: RE | L4: OBJ | M4: RE | N4: OBJ | O4: RE | P4: OBJ | Q4: RE | R4: OBJ | S4: RE | T4: OBJ | U4: RE | V4: OBJ | W4: RE | X4: OBJ | Y4: RE | Z4: OBJ | AA4: RE | AB4: OBJ | AC4: RE | AD4: OBJ | AE4: RE | AF4: % | AG4: OBJ | AH4: RE | AI4: % | AJ4: OBJ | AK4: RE | AL4: % | AM4: OBJ | AN4: RE | AO4: %
A5: 1 | B5: 100323 | C5: CAETANO CUZCO | D5: 8337 | E5: Grupo Caetano | F5: 38 | G5: =IFERROR(VLOOKUP(B5,[2]RETAIL!$B$8:$O$63,3,0),0)-IFERROR(IF(B5=100873,VLOOKUP("ENERO",[2]RETAIL!$B$78:$C$91,2,0),0),0) -> 39 | H5: 38 | I5: =IFERROR(VLOOKUP(B5,[2]RETAIL!$B$8:$O$63,4,0),0)-IFERROR(IF(B5=100873,VLOOKUP("FEBRERO",[2]RETAIL!$B$78:$C$91,2,0),0),0) -> 42 | J5: 39 | K5: =IFERROR(VLOOKUP(B5,[2]RETAIL!$B$8:$O$63,5,0),0)-IFERROR(IF(B5=100873,VLOOKUP("MARZO",[2]RETAIL!$B$78:$C$91,2,0),0),0) -> 42 | L5: 38 | M5: =IFERROR(VLOOKUP(B5,[2]RETAIL!$B$8:$O$63,6,0),0)-IFERROR(IF(B5=100873,VLOOKUP("ABRIL",[2]RETAIL!$B$78:$C$91,2,0),0),0) -> 34 | N5: 38 | O5: =IFERROR(VLOOKUP(B5,[2]RETAIL!$B$8:$O$63,7,0),0)-IFERROR(IF(B5=100873,VLOOKUP("MAYO",[2]RETAIL!$B$78:$C$91,2,0),0),0) -> 34 | P5: 39 | Q5: =IFERROR(VLOOKUP(B5,[2]RETAIL!$B$8:$O$63,8,0),0)-IFERROR(IF(B5=100873,VLOOKUP("JUNIO",[2]RETAIL!$B$78:$C$91,2,0),0),0) -> 39 | S5: =IFERROR(VLOOKUP(B5,[2]RETAIL!$B$8:$O$63,9,0),0)-IFERROR(IF(B5=100873,VLOOKUP("JULIO",[2]RETAIL!$B$78:$C$91,2,0),0),0) -> 0 | U5: =IFERROR(VLOOKUP(B5,[2]RETAIL!$B$8:$O$63,10,0),0)-IFERROR(IF(B5=100873,VLOOKUP("AGOSTO",[2]RETAIL!$B$78:$C$91,2,0),0),0) -> 0 | W5: =IFERROR(VLOOKUP(B5,[2]RETAIL!$B$8:$O$63,11,0),0)-IFERROR(IF(B5=100873,VLOOKUP("SEPTIEMBRE",[2]RETAIL!$B$78:$C$91,2,0),0),0) -> 0 | Y5: =IFERROR(VLOOKUP(B5,[2]RETAIL!$B$8:$O$63,12,0),0)-IFERROR(IF(B5=100873,VLOOKUP("OCTUBRE",[2]RETAIL!$B$78:$C$91,2,0),0),0) -> 0 | AA5: =IFERROR(VLOOKUP(B5,[2]RETAIL!$B$8:$O$63,13,0),0)-IFERROR(IF(B5=100873,VLOOKUP("NOVIEMBRE",[2]RETAIL!$B$78:$C$91,2,0),0),0) -> 0 | AC5: =IFERROR(VLOOKUP(B5,[2]RETAIL!$B$8:$O$63,14,0),0)-IFERROR(IF(B5=100873,VLOOKUP("DICIEMBRE",[2]RETAIL!$B$78:$C$91,2,0),0),0) -> 0 | AD5: =IF($AD$2="ENERO",F5,IF($AD$2="FEBRERO",F5+H5,IF($AD$2="MARZO",F5+H5+J5,IF($AD$2="ABRIL",F5+H5+J5+L5,IF($AD$2="MAYO",F5+H5+J5+L5+N5,IF($AD$2="JUNIO",F5+H5+J5+L5+N5+P5,IF($AD$2="JULIO",F5+H5+J5+L5+N5+P5+R5,IF($AD$2="AGOSTO",F5+H5+J5+L5+N5+P5+R5+T5,IF($AD$2="SEPTIEMBRE",F5+H5+J5+L5+N5+P5+R5+T5+V5,IF($AD$2="OCTUBRE",F5+H5+J5+L5+N5+P5+R5+T5+V5+X5,IF($AD$2="NOVIEMBRE",F5+H5+J5+L5+N5+P5+R5+T5+V5+X5+Z5,IF($AD$2="DICIEMBRE",F5+H5+J5+L5+N5+P5+R5+T5+V5+X5+Z5+AB5,"")))))))))))) -> 230 | AE5: =IFERROR(IF($AD$2="ENERO",G5,IF($AD$2="FEBRERO",G5+I5,IF($AD$2="MARZO",G5+I5+K5,IF($AD$2="ABRIL",G5+I5+K5+M5,IF($AD$2="MAYO",G5+I5+K5+M5+O5,IF($AD$2="JUNIO",G5+I5+K5+M5+O5+Q5,IF($AD$2="JULIO",G5+I5+K5+M5+O5+Q5+S5,IF($AD$2="AGOSTO",G5+I5+K5+M5+O5+Q5+S5+U5,IF($AD$2="SEPTIEMBRE",G5+I5+K5+M5+O5+Q5+S5+U5+W5,IF($AD$2="OCTUBRE",G5+I5+K5+M5+O5+Q5+S5+U5+W5+Y5,IF($AD$2="NOVIEMBRE",G5+I5+K5+M5+O5+Q5+S5+U5+W5+Y5+AA5,IF($AD$2="DICIEMBRE",G5+I5+K5+M5+O5+Q5+S5+U5+W5+Y5+AA5+AC5,"")))))))))))),0) -> 230 | AF5: =IFERROR((AE5/AD5),0) -> 1 | AG5: =+F5+H5+J5+L5+N5+P5+R5+T5+V5+X5+Z5+AB5 -> 230 | AH5: =IFERROR(IF($AD$2="ENERO",G5,IF($AD$2="FEBRERO",G5+I5,IF($AD$2="MARZO",G5+I5+K5,IF($AD$2="ABRIL",G5+I5+K5+M5,IF($AD$2="MAYO",G5+I5+K5+M5+O5,IF($AD$2="JUNIO",G5+I5+K5+M5+O5+Q5,IF($AD$2="JULIO",G5+I5+K5+M5+O5+Q5+S5,IF($AD$2="AGOSTO",G5+I5+K5+M5+O5+Q5+S5+U5,IF($AD$2="SEPTIEMBRE",G5+I5+K5+M5+O5+Q5+S5+U5+W5,IF($AD$2="OCTUBRE",G5+I5+K5+M5+O5+Q5+S5+U5+W5+Y5,IF($AD$2="NOVIEMBRE",G5+I5+K5+M5+O5+Q5+S5+U5+W5+Y5+AA5,IF($AD$2="DICIEMBRE",G5+I5+K5+M5+O5+Q5+S5+U5+W5+Y5+AA5+AC5,"")))))))))))),0) -> 230 | AI5: =IFERROR((AH5/AG5),0) -> 1 | AJ5: =IFERROR(IF($AJ$3="Q1",F5+H5+J5,IF($AJ$3="Q2",L5+N5++P5,IF($AJ$3="Q3",R5+T5+V5,IF($AJ$3="Q4",X5+Z5+AB5,0)))),0) -> 115 | AK5: =IFERROR(IF($AJ$3="Q1",G5+I5+K5,IF($AJ$3="Q2",M5+O5++Q5,IF($AJ$3="Q3",S5+U5+W5,IF($AJ$3="Q4",Y5+AA5+AC5,0)))),0) -> 123 | AL5: =IFERROR((AK5/AJ5),0) -> 1.0695652 | AM5: =IFERROR(IF($AM$3="S 1",F5+H5+J5+L5+N5++P5,IF($AM$3="S 2",R5+T5+V5+X5+Z5+AB5,0)),0) -> 0 | AN5: =IFERROR(IF($AM$3="S 1",G5+I5+K5+M5+O5+Q5,IF($AM$3="S 2",S5+U5+W5+Y5+AA5+AC5,0)),0) -> 0 | AO5: =IFERROR((AN5/AM5),0) -> 0
A6: 1 | B6: 100873 | C6: BYMYCAR MADRID | D6: 51827 | E6: Grupo BYmyCAR | F6: 41 | G6: =IFERROR(VLOOKUP(B6,[2]RETAIL!$B$8:$O$63,3,0),0)-IFERROR(IF(B6=100873,VLOOKUP("ENERO",[2]RETAIL!$B$78:$C$91,2,0),0),0) -> 36 | H6: 42 | I6: =IFERROR(VLOOKUP(B6,[2]RETAIL!$B$8:$O$63,4,0),0)-IFERROR(IF(B6=100873,VLOOKUP("FEBRERO",[2]RETAIL!$B$78:$C$91,2,0),0),0) -> 49 | J6: 42 | K6: =IFERROR(VLOOKUP(B6,[2]RETAIL!$B$8:$O$63,5,0),0)-IFERROR(IF(B6=100873,VLOOKUP("MARZO",[2]RETAIL!$B$78:$C$91,2,0),0),0) -> 66 | L6: 41 | M6: =IFERROR(VLOOKUP(B6,[2]RETAIL!$B$8:$O$63,6,0),0)-IFERROR(IF(B6=100873,VLOOKUP("ABRIL",[2]RETAIL!$B$78:$C$91,2,0),0),0) -> 51 | N6: 42 | O6: =IFERROR(VLOOKUP(B6,[2]RETAIL!$B$8:$O$63,7,0),0)-IFERROR(IF(B6=100873,VLOOKUP("MAYO",[2]RETAIL!$B$78:$C$91,2,0),0),0) -> 53 | P6: 42 | Q6: =IFERROR(VLOOKUP(B6,[2]RETAIL!$B$8:$O$63,8,0),0)-IFERROR(IF(B6=100873,VLOOKUP("JUNIO",[2]RETAIL!$B$78:$C$91,2,0),0),0) -> 57 | S6: =IFERROR(VLOOKUP(B6,[2]RETAIL!$B$8:$O$63,9,0),0)-IFERROR(IF(B6=100873,VLOOKUP("JULIO",[2]RETAIL!$B$78:$C$91,2,0),0),0) -> 0 | U6: =IFERROR(VLOOKUP(B6,[2]RETAIL!$B$8:$O$63,10,0),0)-IFERROR(IF(B6=100873,VLOOKUP("AGOSTO",[2]RETAIL!$B$78:$C$91,2,0),0),0) -> 0 | W6: =IFERROR(VLOOKUP(B6,[2]RETAIL!$B$8:$O$63,11,0),0)-IFERROR(IF(B6=100873,VLOOKUP("SEPTIEMBRE",[2]RETAIL!$B$78:$C$91,2,0),0),0) -> 0 | Y6: =IFERROR(VLOOKUP(B6,[2]RETAIL!$B$8:$O$63,12,0),0)-IFERROR(IF(B6=100873,VLOOKUP("OCTUBRE",[2]RETAIL!$B$78:$C$91,2,0),0),0) -> 0 | AA6: =IFERROR(VLOOKUP(B6,[2]RETAIL!$B$8:$O$63,13,0),0)-IFERROR(IF(B6=100873,VLOOKUP("NOVIEMBRE",[2]RETAIL!$B$78:$C$91,2,0),0),0) -> 0 | AC6: =IFERROR(VLOOKUP(B6,[2]RETAIL!$B$8:$O$63,14,0),0)-IFERROR(IF(B6=100873,VLOOKUP("DICIEMBRE",[2]RETAIL!$B$78:$C$91,2,0),0),0) -> 0 | AD6: =IF($AD$2="ENERO",F6,IF($AD$2="FEBRERO",F6+H6,IF($AD$2="MARZO",F6+H6+J6,IF($AD$2="ABRIL",F6+H6+J6+L6,IF($AD$2="MAYO",F6+H6+J6+L6+N6,IF($AD$2="JUNIO",F6+H6+J6+L6+N6+P6,IF($AD$2="JULIO",F6+H6+J6+L6+N6+P6+R6,IF($AD$2="AGOSTO",F6+H6+J6+L6+N6+P6+R6+T6,IF($AD$2="SEPTIEMBRE",F6+H6+J6+L6+N6+P6+R6+T6+V6,IF($AD$2="OCTUBRE",F6+H6+J6+L6+N6+P6+R6+T6+V6+X6,IF($AD$2="NOVIEMBRE",F6+H6+J6+L6+N6+P6+R6+T6+V6+X6+Z6,IF($AD$2="DICIEMBRE",F6+H6+J6+L6+N6+P6+R6+T6+V6+X6+Z6+AB6,"")))))))))))) -> 250 | AE6: =IFERROR(IF($AD$2="ENERO",G6,IF($AD$2="FEBRERO",G6+I6,IF($AD$2="MARZO",G6+I6+K6,IF($AD$2="ABRIL",G6+I6+K6+M6,IF($AD$2="MAYO",G6+I6+K6+M6+O6,IF($AD$2="JUNIO",G6+I6+K6+M6+O6+Q6,IF($AD$2="JULIO",G6+I6+K6+M6+O6+Q6+S6,IF($AD$2="AGOSTO",G6+I6+K6+M6+O6+Q6+S6+U6,IF($AD$2="SEPTIEMBRE",G6+I6+K6+M6+O6+Q6+S6+U6+W6,IF($AD$2="OCTUBRE",G6+I6+K6+M6+O6+Q6+S6+U6+W6+Y6,IF($AD$2="NOVIEMBRE",G6+I6+K6+M6+O6+Q6+S6+U6+W6+Y6+AA6,IF($AD$2="DICIEMBRE",G6+I6+K6+M6+O6+Q6+S6+U6+W6+Y6+AA6+AC6,"")))))))))))),0) -> 312 | AF6: =IFERROR((AE6/AD6),0) -> 1.248 | AG6: =+F6+H6+J6+L6+N6+P6+R6+T6+V6+X6+Z6+AB6 -> 250 | AH6: =IFERROR(IF($AD$2="ENERO",G6,IF($AD$2="FEBRERO",G6+I6,IF($AD$2="MARZO",G6+I6+K6,IF($AD$2="ABRIL",G6+I6+K6+M6,IF($AD$2="MAYO",G6+I6+K6+M6+O6,IF($AD$2="JUNIO",G6+I6+K6+M6+O6+Q6,IF($AD$2="JULIO",G6+I6+K6+M6+O6+Q6+S6,IF($AD$2="AGOSTO",G6+I6+K6+M6+O6+Q6+S6+U6,IF($AD$2="SEPTIEMBRE",G6+I6+K6+M6+O6+Q6+S6+U6+W6,IF($AD$2="OCTUBRE",G6+I6+K6+M6+O6+Q6+S6+U6+W6+Y6,IF($AD$2="NOVIEMBRE",G6+I6+K6+M6+O6+Q6+S6+U6+W6+Y6+AA6,IF($AD$2="DICIEMBRE",G6+I6+K6+M6+O6+Q6+S6+U6+W6+Y6+AA6+AC6,"")))))))))))),0) -> 312 | AI6: =IFERROR((AH6/AG6),0) -> 1.248 | AJ6: =IFERROR(IF($AJ$3="Q1",F6+H6+J6,IF($AJ$3="Q2",L6+N6++P6,IF($AJ$3="Q3",R6+T6+V6,IF($AJ$3="Q4",X6+Z6+AB6,0)))),0) -> 125 | AK6: =IFERROR(IF($AJ$3="Q1",G6+I6+K6,IF($AJ$3="Q2",M6+O6++Q6,IF($AJ$3="Q3",S6+U6+W6,IF($AJ$3="Q4",Y6+AA6+AC6,0)))),0) -> 151 | AL6: =IFERROR((AK6/AJ6),0) -> 1.208 | AM6: =IFERROR(IF($AM$3="S 1",F6+H6+J6+L6+N6++P6,IF($AM$3="S 2",R6+T6+V6+X6+Z6+AB6,0)),0) -> 0 | AN6: =IFERROR(IF($AM$3="S 1",G6+I6+K6+M6+O6+Q6,IF($AM$3="S 2",S6+U6+W6+Y6+AA6+AC6,0)),0) -> 0 | AO6: =IFERROR((AN6/AM6),0) -> 0
A7: 1 | B7: 100389 | C7: CANAAUTO | D7: 20822 | E7: Canaauto | F7: 22 | G7: =IFERROR(VLOOKUP(B7,[2]RETAIL!$B$8:$O$63,3,0),0)-IFERROR(IF(B7=100873,VLOOKUP("ENERO",[2]RETAIL!$B$78:$C$91,2,0),0),0) -> 4 | H7: 22 | I7: =IFERROR(VLOOKUP(B7,[2]RETAIL!$B$8:$O$63,4,0),0)-IFERROR(IF(B7=100873,VLOOKUP("FEBRERO",[2]RETAIL!$B$78:$C$91,2,0),0),0) -> 42 | J7: 22 | K7: =IFERROR(VLOOKUP(B7,[2]RETAIL!$B$8:$O$63,5,0),0)-IFERROR(IF(B7=100873,VLOOKUP("MARZO",[2]RETAIL!$B$78:$C$91,2,0),0),0) -> 25 | L7: 22 | M7: =IFERROR(VLOOKUP(B7,[2]RETAIL!$B$8:$O$63,6,0),0)-IFERROR(IF(B7=100873,VLOOKUP("ABRIL",[2]RETAIL!$B$78:$C$91,2,0),0),0) -> 18 | N7: 22 | O7: =IFERROR(VLOOKUP(B7,[2]RETAIL!$B$8:$O$63,7,0),0)-IFERROR(IF(B7=100873,VLOOKUP("MAYO",[2]RETAIL!$B$78:$C$91,2,0),0),0) -> 18 | P7: 22 | Q7: =IFERROR(VLOOKUP(B7,[2]RETAIL!$B$8:$O$63,8,0),0)-IFERROR(IF(B7=100873,VLOOKUP("JUNIO",[2]RETAIL!$B$78:$C$91,2,0),0),0) -> 32 | S7: =IFERROR(VLOOKUP(B7,[2]RETAIL!$B$8:$O$63,9,0),0)-IFERROR(IF(B7=100873,VLOOKUP("JULIO",[2]RETAIL!$B$78:$C$91,2,0),0),0) -> 0 | U7: =IFERROR(VLOOKUP(B7,[2]RETAIL!$B$8:$O$63,10,0),0)-IFERROR(IF(B7=100873,VLOOKUP("AGOSTO",[2]RETAIL!$B$78:$C$91,2,0),0),0) -> 0 | W7: =IFERROR(VLOOKUP(B7,[2]RETAIL!$B$8:$O$63,11,0),0)-IFERROR(IF(B7=100873,VLOOKUP("SEPTIEMBRE",[2]RETAIL!$B$78:$C$91,2,0),0),0) -> 0 | Y7: =IFERROR(VLOOKUP(B7,[2]RETAIL!$B$8:$O$63,12,0),0)-IFERROR(IF(B7=100873,VLOOKUP("OCTUBRE",[2]RETAIL!$B$78:$C$91,2,0),0),0) -> 0 | AA7: =IFERROR(VLOOKUP(B7,[2]RETAIL!$B$8:$O$63,13,0),0)-IFERROR(IF(B7=100873,VLOOKUP("NOVIEMBRE",[2]RETAIL!$B$78:$C$91,2,0),0),0) -> 0 | AC7: =IFERROR(VLOOKUP(B7,[2]RETAIL!$B$8:$O$63,14,0),0)-IFERROR(IF(B7=100873,VLOOKUP("DICIEMBRE",[2]RETAIL!$B$78:$C$91,2,0),0),0) -> 0 | AD7: =IF($AD$2="ENERO",F7,IF($AD$2="FEBRERO",F7+H7,IF($AD$2="MARZO",F7+H7+J7,IF($AD$2="ABRIL",F7+H7+J7+L7,IF($AD$2="MAYO",F7+H7+J7+L7+N7,IF($AD$2="JUNIO",F7+H7+J7+L7+N7+P7,IF($AD$2="JULIO",F7+H7+J7+L7+N7+P7+R7,IF($AD$2="AGOSTO",F7+H7+J7+L7+N7+P7+R7+T7,IF($AD$2="SEPTIEMBRE",F7+H7+J7+L7+N7+P7+R7+T7+V7,IF($AD$2="OCTUBRE",F7+H7+J7+L7+N7+P7+R7+T7+V7+X7,IF($AD$2="NOVIEMBRE",F7+H7+J7+L7+N7+P7+R7+T7+V7+X7+Z7,IF($AD$2="DICIEMBRE",F7+H7+J7+L7+N7+P7+R7+T7+V7+X7+Z7+AB7,"")))))))))))) -> 132 | AE7: =IFERROR(IF($AD$2="ENERO",G7,IF($AD$2="FEBRERO",G7+I7,IF($AD$2="MARZO",G7+I7+K7,IF($AD$2="ABRIL",G7+I7+K7+M7,IF($AD$2="MAYO",G7+I7+K7+M7+O7,IF($AD$2="JUNIO",G7+I7+K7+M7+O7+Q7,IF($AD$2="JULIO",G7+I7+K7+M7+O7+Q7+S7,IF($AD$2="AGOSTO",G7+I7+K7+M7+O7+Q7+S7+U7,IF($AD$2="SEPTIEMBRE",G7+I7+K7+M7+O7+Q7+S7+U7+W7,IF($AD$2="OCTUBRE",G7+I7+K7+M7+O7+Q7+S7+U7+W7+Y7,IF($AD$2="NOVIEMBRE",G7+I7+K7+M7+O7+Q7+S7+U7+W7+Y7+AA7,IF($AD$2="DICIEMBRE",G7+I7+K7+M7+O7+Q7+S7+U7+W7+Y7+AA7+AC7,"")))))))))))),0) -> 139 | AF7: =IFERROR((AE7/AD7),0) -> 1.0530303 | AG7: =+F7+H7+J7+L7+N7+P7+R7+T7+V7+X7+Z7+AB7 -> 132 | AH7: =IFERROR(IF($AD$2="ENERO",G7,IF($AD$2="FEBRERO",G7+I7,IF($AD$2="MARZO",G7+I7+K7,IF($AD$2="ABRIL",G7+I7+K7+M7,IF($AD$2="MAYO",G7+I7+K7+M7+O7,IF($AD$2="JUNIO",G7+I7+K7+M7+O7+Q7,IF($AD$2="JULIO",G7+I7+K7+M7+O7+Q7+S7,IF($AD$2="AGOSTO",G7+I7+K7+M7+O7+Q7+S7+U7,IF($AD$2="SEPTIEMBRE",G7+I7+K7+M7+O7+Q7+S7+U7+W7,IF($AD$2="OCTUBRE",G7+I7+K7+M7+O7+Q7+S7+U7+W7+Y7,IF($AD$2="NOVIEMBRE",G7+I7+K7+M7+O7+Q7+S7+U7+W7+Y7+AA7,IF($AD$2="DICIEMBRE",G7+I7+K7+M7+O7+Q7+S7+U7+W7+Y7+AA7+AC7,"")))))))))))),0) -> 139 | AI7: =IFERROR((AH7/AG7),0) -> 1.0530303 | AJ7: =IFERROR(IF($AJ$3="Q1",F7+H7+J7,IF($AJ$3="Q2",L7+N7++P7,IF($AJ$3="Q3",R7+T7+V7,IF($AJ$3="Q4",X7+Z7+AB7,0)))),0) -> 66 | AK7: =IFERROR(IF($AJ$3="Q1",G7+I7+K7,IF($AJ$3="Q2",M7+O7++Q7,IF($AJ$3="Q3",S7+U7+W7,IF($AJ$3="Q4",Y7+AA7+AC7,0)))),0) -> 71 | AL7: =IFERROR((AK7/AJ7),0) -> 1.0757576 | AM7: =IFERROR(IF($AM$3="S 1",F7+H7+J7+L7+N7++P7,IF($AM$3="S 2",R7+T7+V7+X7+Z7+AB7,0)),0) -> 0 | AN7: =IFERROR(IF($AM$3="S 1",G7+I7+K7+M7+O7+Q7,IF($AM$3="S 2",S7+U7+W7+Y7+AA7+AC7,0)),0) -> 0 | AO7: =IFERROR((AN7/AM7),0) -> 0
A8: 1 | B8: 100738 | C8: MARMOTOR | D8: 40230 | E8: Marmotor | F8: 18 | G8: =IFERROR(VLOOKUP(B8,[2]RETAIL!$B$8:$O$63,3,0),0)-IFERROR(IF(B8=100873,VLOOKUP("ENERO",[2]RETAIL!$B$78:$C$91,2,0),0),0) -> 11 | H8: 19 | I8: =IFERROR(VLOOKUP(B8,[2]RETAIL!$B$8:$O$63,4,0),0)-IFERROR(IF(B8=100873,VLOOKUP("FEBRERO",[2]RETAIL!$B$78:$C$91,2,0),0),0) -> 7 | J8: 19 | K8: =IFERROR(VLOOKUP(B8,[2]RETAIL!$B$8:$O$63,5,0),0)-IFERROR(IF(B8=100873,VLOOKUP("MARZO",[2]RETAIL!$B$78:$C$91,2,0),0),0) -> 14 | L8: 18 | M8: =IFERROR(VLOOKUP(B8,[2]RETAIL!$B$8:$O$63,6,0),0)-IFERROR(IF(B8=100873,VLOOKUP("ABRIL",[2]RETAIL!$B$78:$C$91,2,0),0),0) -> 11 | N8: 19 | O8: =IFERROR(VLOOKUP(B8,[2]RETAIL!$B$8:$O$63,7,0),0)-IFERROR(IF(B8=100873,VLOOKUP("MAYO",[2]RETAIL!$B$78:$C$91,2,0),0),0) -> 12 | P8: 19 | Q8: =IFERROR(VLOOKUP(B8,[2]RETAIL!$B$8:$O$63,8,0),0)-IFERROR(IF(B8=100873,VLOOKUP("JUNIO",[2]RETAIL!$B$78:$C$91,2,0),0),0) -> 9 | S8: =IFERROR(VLOOKUP(B8,[2]RETAIL!$B$8:$O$63,9,0),0)-IFERROR(IF(B8=100873,VLOOKUP("JULIO",[2]RETAIL!$B$78:$C$91,2,0),0),0) -> 0 | U8: =IFERROR(VLOOKUP(B8,[2]RETAIL!$B$8:$O$63,10,0),0)-IFERROR(IF(B8=100873,VLOOKUP("AGOSTO",[2]RETAIL!$B$78:$C$91,2,0),0),0) -> 0 | W8: =IFERROR(VLOOKUP(B8,[2]RETAIL!$B$8:$O$63,11,0),0)-IFERROR(IF(B8=100873,VLOOKUP("SEPTIEMBRE",[2]RETAIL!$B$78:$C$91,2,0),0),0) -> 0 | Y8: =IFERROR(VLOOKUP(B8,[2]RETAIL!$B$8:$O$63,12,0),0)-IFERROR(IF(B8=100873,VLOOKUP("OCTUBRE",[2]RETAIL!$B$78:$C$91,2,0),0),0) -> 0 | AA8: =IFERROR(VLOOKUP(B8,[2]RETAIL!$B$8:$O$63,13,0),0)-IFERROR(IF(B8=100873,VLOOKUP("NOVIEMBRE",[2]RETAIL!$B$78:$C$91,2,0),0),0) -> 0 | AC8: =IFERROR(VLOOKUP(B8,[2]RETAIL!$B$8:$O$63,14,0),0)-IFERROR(IF(B8=100873,VLOOKUP("DICIEMBRE",[2]RETAIL!$B$78:$C$91,2,0),0),0) -> 0 | AD8: =IF($AD$2="ENERO",F8,IF($AD$2="FEBRERO",F8+H8,IF($AD$2="MARZO",F8+H8+J8,IF($AD$2="ABRIL",F8+H8+J8+L8,IF($AD$2="MAYO",F8+H8+J8+L8+N8,IF($AD$2="JUNIO",F8+H8+J8+L8+N8+P8,IF($AD$2="JULIO",F8+H8+J8+L8+N8+P8+R8,IF($AD$2="AGOSTO",F8+H8+J8+L8+N8+P8+R8+T8,IF($AD$2="SEPTIEMBRE",F8+H8+J8+L8+N8+P8+R8+T8+V8,IF($AD$2="OCTUBRE",F8+H8+J8+L8+N8+P8+R8+T8+V8+X8,IF($AD$2="NOVIEMBRE",F8+H8+J8+L8+N8+P8+R8+T8+V8+X8+Z8,IF($AD$2="DICIEMBRE",F8+H8+J8+L8+N8+P8+R8+T8+V8+X8+Z8+AB8,"")))))))))))) -> 112 | AE8: =IFERROR(IF($AD$2="ENERO",G8,IF($AD$2="FEBRERO",G8+I8,IF($AD$2="MARZO",G8+I8+K8,IF($AD$2="ABRIL",G8+I8+K8+M8,IF($AD$2="MAYO",G8+I8+K8+M8+O8,IF($AD$2="JUNIO",G8+I8+K8+M8+O8+Q8,IF($AD$2="JULIO",G8+I8+K8+M8+O8+Q8+S8,IF($AD$2="AGOSTO",G8+I8+K8+M8+O8+Q8+S8+U8,IF($AD$2="SEPTIEMBRE",G8+I8+K8+M8+O8+Q8+S8+U8+W8,IF($AD$2="OCTUBRE",G8+I8+K8+M8+O8+Q8+S8+U8+W8+Y8,IF($AD$2="NOVIEMBRE",G8+I8+K8+M8+O8+Q8+S8+U8+W8+Y8+AA8,IF($AD$2="DICIEMBRE",G8+I8+K8+M8+O8+Q8+S8+U8+W8+Y8+AA8+AC8,"")))))))))))),0) -> 64 | AF8: =IFERROR((AE8/AD8),0) -> 0.57142857 | AG8: =+F8+H8+J8+L8+N8+P8+R8+T8+V8+X8+Z8+AB8 -> 112 | AH8: =IFERROR(IF($AD$2="ENERO",G8,IF($AD$2="FEBRERO",G8+I8,IF($AD$2="MARZO",G8+I8+K8,IF($AD$2="ABRIL",G8+I8+K8+M8,IF($AD$2="MAYO",G8+I8+K8+M8+O8,IF($AD$2="JUNIO",G8+I8+K8+M8+O8+Q8,IF($AD$2="JULIO",G8+I8+K8+M8+O8+Q8+S8,IF($AD$2="AGOSTO",G8+I8+K8+M8+O8+Q8+S8+U8,IF($AD$2="SEPTIEMBRE",G8+I8+K8+M8+O8+Q8+S8+U8+W8,IF($AD$2="OCTUBRE",G8+I8+K8+M8+O8+Q8+S8+U8+W8+Y8,IF($AD$2="NOVIEMBRE",G8+I8+K8+M8+O8+Q8+S8+U8+W8+Y8+AA8,IF($AD$2="DICIEMBRE",G8+I8+K8+M8+O8+Q8+S8+U8+W8+Y8+AA8+AC8,"")))))))))))),0) -> 64 | AI8: =IFERROR((AH8/AG8),0) -> 0.57142857 | AJ8: =IFERROR(IF($AJ$3="Q1",F8+H8+J8,IF($AJ$3="Q2",L8+N8++P8,IF($AJ$3="Q3",R8+T8+V8,IF($AJ$3="Q4",X8+Z8+AB8,0)))),0) -> 56 | AK8: =IFERROR(IF($AJ$3="Q1",G8+I8+K8,IF($AJ$3="Q2",M8+O8++Q8,IF($AJ$3="Q3",S8+U8+W8,IF($AJ$3="Q4",Y8+AA8+AC8,0)))),0) -> 32 | AL8: =IFERROR((AK8/AJ8),0) -> 0.57142857 | AM8: =IFERROR(IF($AM$3="S 1",F8+H8+J8+L8+N8++P8,IF($AM$3="S 2",R8+T8+V8+X8+Z8+AB8,0)),0) -> 0 | AN8: =IFERROR(IF($AM$3="S 1",G8+I8+K8+M8+O8+Q8,IF($AM$3="S 2",S8+U8+W8+Y8+AA8+AC8,0)),0) -> 0 | AO8: =IFERROR((AN8/AM8),0) -> 0
B9: TOTAL DISTRITO 1 | F9: =SUM(F5:F8) -> 119 | G9: =SUM(G5:G8) -> 90 | H9: =SUM(H5:H8) -> 121 | I9: =SUM(I5:I8) -> 140 | J9: =SUM(J5:J8) -> 122 | K9: =SUM(K5:K8) -> 147 | L9: =SUM(L5:L8) -> 119 | M9: =SUM(M5:M8) -> 114 | ... AC9: =SUM(AC5:AC8) -> 0 | AD9: =IF($AD$2="ENERO",F9,IF($AD$2="FEBRERO",F9+H9,IF($AD$2="MARZO",F9+H9+J9,IF($AD$2="ABRIL",F9+H9+J9+L9,IF($AD$2="MAYO",F9+H9+J9+L9+N9,IF($AD$2="JUNIO",F9+H9+J9+L9+N9+P9,IF($AD$2="JULIO",F9+H9+J9+L9+N9+P9+R9,IF($AD$2="AGOSTO",F9+H9+J9+L9+N9+P9+R9+T9,IF($AD$2="SEPTIEMBRE",F9+H9+J9+L9+N9+P9+R9+T9+V9,IF($AD$2="OCTUBRE",F9+H9+J9+L9+N9+P9+R9+T9+V9+X9,IF($AD$2="NOVIEMBRE",F9+H9+J9+L9+N9+P9+R9+T9+V9+X9+Z9,IF($AD$2="DICIEMBRE",F9+H9+J9+L9+N9+P9+R9+T9+V9+X9+Z9+AB9,"")))))))))))) -> 724 | AE9: =IF($AD$2="ENERO",G9,IF($AD$2="FEBRERO",G9+I9,IF($AD$2="MARZO",G9+I9+K9,IF($AD$2="ABRIL",G9+I9+K9+M9,IF($AD$2="MAYO",G9+I9+K9+M9+O9,IF($AD$2="JUNIO",G9+I9+K9+M9+O9+Q9,IF($AD$2="JULIO",G9+I9+K9+M9+O9+Q9+S9,IF($AD$2="AGOSTO",G9+I9+K9+M9+O9+Q9+S9+U9,IF($AD$2="SEPTIEMBRE",G9+I9+K9+M9+O9+Q9+S9+U9+W9,IF($AD$2="OCTUBRE",G9+I9+K9+M9+O9+Q9+S9+U9+W9+Y9,IF($AD$2="NOVIEMBRE",G9+I9+K9+M9+O9+Q9+S9+U9+W9+Y9+AA9,IF($AD$2="DICIEMBRE",G9+I9+K9+M9+O9+Q9+S9+U9+W9+Y9+AA9+AC9,"")))))))))))) -> 745 | AF9: =IFERROR((AE9/AD9),0) -> 1.0290055 | AG9: =+F9+H9+J9+L9+N9+P9+R9+T9+V9+X9+Z9+AB9 -> 724 | AH9: =IF($AD$2="ENERO",G9,IF($AD$2="FEBRERO",G9+I9,IF($AD$2="MARZO",G9+I9+K9,IF($AD$2="ABRIL",G9+I9+K9+M9,IF($AD$2="MAYO",G9+I9+K9+M9+O9,IF($AD$2="JUNIO",G9+I9+K9+M9+O9+Q9,IF($AD$2="JULIO",G9+I9+K9+M9+O9+Q9+S9,IF($AD$2="AGOSTO",G9+I9+K9+M9+O9+Q9+S9+U9,IF($AD$2="SEPTIEMBRE",G9+I9+K9+M9+O9+Q9+S9+U9+W9,IF($AD$2="OCTUBRE",G9+I9+K9+M9+O9+Q9+S9+U9+W9+Y9,IF($AD$2="NOVIEMBRE",G9+I9+K9+M9+O9+Q9+S9+U9+W9+Y9+AA9,IF($AD$2="DICIEMBRE",G9+I9+K9+M9+O9+Q9+S9+U9+W9+Y9+AA9+AC9,"")))))))))))) -> 745 | AI9: =IFERROR((AH9/AG9),0) -> 1.0290055 | AJ9: =IFERROR(IF($AJ$3="Q1",F9+H9+J9,IF($AJ$3="Q2",L9+N9++P9,IF($AJ$3="Q3",R9+T9+V9,IF($AJ$3="Q4",X9+Z9+AB9,0)))),0) -> 362 | AK9: =IFERROR(IF($AJ$3="Q1",G9+I9+K9,IF($AJ$3="Q2",M9+O9++Q9,IF($AJ$3="Q3",S9+U9+W9,IF($AJ$3="Q4",Y9+AA9+AC9,0)))),0) -> 377 | AL9: =IFERROR((AK9/AJ9),0) -> 1.0414365 | AM9: =IFERROR(IF($AM$3="S 1",F9+H9+J9+L9+N9++P9,IF($AM$3="S 2",R9+T9+V9+X9+Z9+AB9,0)),0) -> 0 | AN9: =IFERROR(IF($AM$3="S 1",G9+I9+K9+M9+O9+Q9,IF($AM$3="S 2",S9+U9+W9+Y9+AA9+AC9,0)),0) -> 0 | AO9: =IFERROR((AN9/AM9),0) -> 0
A10: 2 | B10: 100213 | C10: MOVILNORTE | D10: 7450 | E10: Grupo Momentum | F10: 46 | G10: =IFERROR(VLOOKUP(B10,[2]RETAIL!$B$8:$O$63,3,0),0)-IFERROR(IF(B10=100873,VLOOKUP("ENERO",[2]RETAIL!$B$78:$C$91,2,0),0),0) -> 38 | H10: 47 | I10: =IFERROR(VLOOKUP(B10,[2]RETAIL!$B$8:$O$63,4,0),0)-IFERROR(IF(B10=100873,VLOOKUP("FEBRERO",[2]RETAIL!$B$78:$C$91,2,0),0),0) -> 51 | J10: 47 | K10: =IFERROR(VLOOKUP(B10,[2]RETAIL!$B$8:$O$63,5,0),0)-IFERROR(IF(B10=100873,VLOOKUP("MARZO",[2]RETAIL!$B$78:$C$91,2,0),0),0) -> 63 | L10: 46 | M10: =IFERROR(VLOOKUP(B10,[2]RETAIL!$B$8:$O$63,6,0),0)-IFERROR(IF(B10=100873,VLOOKUP("ABRIL",[2]RETAIL!$B$78:$C$91,2,0),0),0) -> 48 | N10: 47 | O10: =IFERROR(VLOOKUP(B10,[2]RETAIL!$B$8:$O$63,7,0),0)-IFERROR(IF(B10=100873,VLOOKUP("MAYO",[2]RETAIL!$B$78:$C$91,2,0),0),0) -> 50 | P10: 47 | Q10: =IFERROR(VLOOKUP(B10,[2]RETAIL!$B$8:$O$63,8,0),0)-IFERROR(IF(B10=100873,VLOOKUP("JUNIO",[2]RETAIL!$B$78:$C$91,2,0),0),0) -> 49 | S10: =IFERROR(VLOOKUP(B10,[2]RETAIL!$B$8:$O$63,9,0),0)-IFERROR(IF(B10=100873,VLOOKUP("JULIO",[2]RETAIL!$B$78:$C$91,2,0),0),0) -> 0 | U10: =IFERROR(VLOOKUP(B10,[2]RETAIL!$B$8:$O$63,10,0),0)-IFERROR(IF(B10=100873,VLOOKUP("AGOSTO",[2]RETAIL!$B$78:$C$91,2,0),0),0) -> 0 | W10: =IFERROR(VLOOKUP(B10,[2]RETAIL!$B$8:$O$63,11,0),0)-IFERROR(IF(B10=100873,VLOOKUP("SEPTIEMBRE",[2]RETAIL!$B$78:$C$91,2,0),0),0) -> 0 | Y10: =IFERROR(VLOOKUP(B10,[2]RETAIL!$B$8:$O$63,12,0),0)-IFERROR(IF(B10=100873,VLOOKUP("OCTUBRE",[2]RETAIL!$B$78:$C$91,2,0),0),0) -> 0 | AA10: =IFERROR(VLOOKUP(B10,[2]RETAIL!$B$8:$O$63,13,0),0)-IFERROR(IF(B10=100873,VLOOKUP("NOVIEMBRE",[2]RETAIL!$B$78:$C$91,2,0),0),0) -> 0 | AC10: =IFERROR(VLOOKUP(B10,[2]RETAIL!$B$8:$O$63,14,0),0)-IFERROR(IF(B10=100873,VLOOKUP("DICIEMBRE",[2]RETAIL!$B$78:$C$91,2,0),0),0) -> 0 | AD10: =IF($AD$2="ENERO",F10,IF($AD$2="FEBRERO",F10+H10,IF($AD$2="MARZO",F10+H10+J10,IF($AD$2="ABRIL",F10+H10+J10+L10,IF($AD$2="MAYO",F10+H10+J10+L10+N10,IF($AD$2="JUNIO",F10+H10+J10+L10+N10+P10,IF($AD$2="JULIO",F10+H10+J10+L10+N10+P10+R10,IF($AD$2="AGOSTO",F10+H10+J10+L10+N10+P10+R10+T10,IF($AD$2="SEPTIEMBRE",F10+H10+J10+L10+N10+P10+R10+T10+V10,IF($AD$2="OCTUBRE",F10+H10+J10+L10+N10+P10+R10+T10+V10+X10,IF($AD$2="NOVIEMBRE",F10+H10+J10+L10+N10+P10+R10+T10+V10+X10+Z10,IF($AD$2="DICIEMBRE",F10+H10+J10+L10+N10+P10+R10+T10+V10+X10+Z10+AB10,"")))))))))))) -> 280 | AE10: =IFERROR(IF($AD$2="ENERO",G10,IF($AD$2="FEBRERO",G10+I10,IF($AD$2="MARZO",G10+I10+K10,IF($AD$2="ABRIL",G10+I10+K10+M10,IF($AD$2="MAYO",G10+I10+K10+M10+O10,IF($AD$2="JUNIO",G10+I10+K10+M10+O10+Q10,IF($AD$2="JULIO",G10+I10+K10+M10+O10+Q10+S10,IF($AD$2="AGOSTO",G10+I10+K10+M10+O10+Q10+S10+U10,IF($AD$2="SEPTIEMBRE",G10+I10+K10+M10+O10+Q10+S10+U10+W10,IF($AD$2="OCTUBRE",G10+I10+K10+M10+O10+Q10+S10+U10+W10+Y10,IF($AD$2="NOVIEMBRE",G10+I10+K10+M10+O10+Q10+S10+U10+W10+Y10+AA10,IF($AD$2="DICIEMBRE",G10+I10+K10+M10+O10+Q10+S10+U10+W10+Y10+AA10+AC10,"")))))))))))),0) -> 299 | AF10: =IFERROR((AH10/AD10),0) -> 1.0678571 | AG10: =+F10+H10+J10+L10+N10+P10+R10+T10+V10+X10+Z10+AB10 -> 280 | AH10: =IFERROR(IF($AD$2="ENERO",G10,IF($AD$2="FEBRERO",G10+I10,IF($AD$2="MARZO",G10+I10+K10,IF($AD$2="ABRIL",G10+I10+K10+M10,IF($AD$2="MAYO",G10+I10+K10+M10+O10,IF($AD$2="JUNIO",G10+I10+K10+M10+O10+Q10,IF($AD$2="JULIO",G10+I10+K10+M10+O10+Q10+S10,IF($AD$2="AGOSTO",G10+I10+K10+M10+O10+Q10+S10+U10,IF($AD$2="SEPTIEMBRE",G10+I10+K10+M10+O10+Q10+S10+U10+W10,IF($AD$2="OCTUBRE",G10+I10+K10+M10+O10+Q10+S10+U10+W10+Y10,IF($AD$2="NOVIEMBRE",G10+I10+K10+M10+O10+Q10+S10+U10+W10+Y10+AA10,IF($AD$2="DICIEMBRE",G10+I10+K10+M10+O10+Q10+S10+U10+W10+Y10+AA10+AC10,"")))))))))))),0) -> 299 | AI10: =IFERROR((AH10/AG10),0) -> 1.0678571 | AJ10: =IFERROR(IF($AJ$3="Q1",F10+H10+J10,IF($AJ$3="Q2",L10+N10++P10,IF($AJ$3="Q3",R10+T10+V10,IF($AJ$3="Q4",X10+Z10+AB10,0)))),0) -> 140 | AK10: =IFERROR(IF($AJ$3="Q1",G10+I10+K10,IF($AJ$3="Q2",M10+O10++Q10,IF($AJ$3="Q3",S10+U10+W10,IF($AJ$3="Q4",Y10+AA10+AC10,0)))),0) -> 152 | AL10: =IFERROR((AK10/AJ10),0) -> 1.0857143 | AM10: =IFERROR(IF($AM$3="S 1",F10+H10+J10+L10+N10++P10,IF($AM$3="S 2",R10+T10+V10+X10+Z10+AB10,0)),0) -> 0 | AN10: =IFERROR(IF($AM$3="S 1",G10+I10+K10+M10+O10+Q10,IF($AM$3="S 2",S10+U10+W10+Y10+AA10+AC10,0)),0) -> 0 | AO10: =IFERROR((AN10/AM10),0) -> 0
A11: 2 | B11: 100319 | C11: VEHINTER | D11: 7450 | E11: Grupo Momentum | F11: 47 | G11: =IFERROR(VLOOKUP(B11,[2]RETAIL!$B$8:$O$63,3,0),0)-IFERROR(IF(B11=100873,VLOOKUP("ENERO",[2]RETAIL!$B$78:$C$91,2,0),0),0) -> 50 | H11: 49 | I11: =IFERROR(VLOOKUP(B11,[2]RETAIL!$B$8:$O$63,4,0),0)-IFERROR(IF(B11=100873,VLOOKUP("FEBRERO",[2]RETAIL!$B$78:$C$91,2,0),0),0) -> 57 | J11: 49 | K11: =IFERROR(VLOOKUP(B11,[2]RETAIL!$B$8:$O$63,5,0),0)-IFERROR(IF(B11=100873,VLOOKUP("MARZO",[2]RETAIL!$B$78:$C$91,2,0),0),0) -> 63 | L11: 47 | M11: =IFERROR(VLOOKUP(B11,[2]RETAIL!$B$8:$O$63,6,0),0)-IFERROR(IF(B11=100873,VLOOKUP("ABRIL",[2]RETAIL!$B$78:$C$91,2,0),0),0) -> 56 | N11: 49 | O11: =IFERROR(VLOOKUP(B11,[2]RETAIL!$B$8:$O$63,7,0),0)-IFERROR(IF(B11=100873,VLOOKUP("MAYO",[2]RETAIL!$B$78:$C$91,2,0),0),0) -> 44 | P11: 49 | Q11: =IFERROR(VLOOKUP(B11,[2]RETAIL!$B$8:$O$63,8,0),0)-IFERROR(IF(B11=100873,VLOOKUP("JUNIO",[2]RETAIL!$B$78:$C$91,2,0),0),0) -> 60 | S11: =IFERROR(VLOOKUP(B11,[2]RETAIL!$B$8:$O$63,9,0),0)-IFERROR(IF(B11=100873,VLOOKUP("JULIO",[2]RETAIL!$B$78:$C$91,2,0),0),0) -> 0 | U11: =IFERROR(VLOOKUP(B11,[2]RETAIL!$B$8:$O$63,10,0),0)-IFERROR(IF(B11=100873,VLOOKUP("AGOSTO",[2]RETAIL!$B$78:$C$91,2,0),0),0) -> 0 | W11: =IFERROR(VLOOKUP(B11,[2]RETAIL!$B$8:$O$63,11,0),0)-IFERROR(IF(B11=100873,VLOOKUP("SEPTIEMBRE",[2]RETAIL!$B$78:$C$91,2,0),0),0) -> 0 | Y11: =IFERROR(VLOOKUP(B11,[2]RETAIL!$B$8:$O$63,12,0),0)-IFERROR(IF(B11=100873,VLOOKUP("OCTUBRE",[2]RETAIL!$B$78:$C$91,2,0),0),0) -> 0 | AA11: =IFERROR(VLOOKUP(B11,[2]RETAIL!$B$8:$O$63,13,0),0)-IFERROR(IF(B11=100873,VLOOKUP("NOVIEMBRE",[2]RETAIL!$B$78:$C$91,2,0),0),0) -> 0 | AC11: =IFERROR(VLOOKUP(B11,[2]RETAIL!$B$8:$O$63,14,0),0)-IFERROR(IF(B11=100873,VLOOKUP("DICIEMBRE",[2]RETAIL!$B$78:$C$91,2,0),0),0) -> 0 | AD11: =IF($AD$2="ENERO",F11,IF($AD$2="FEBRERO",F11+H11,IF($AD$2="MARZO",F11+H11+J11,IF($AD$2="ABRIL",F11+H11+J11+L11,IF($AD$2="MAYO",F11+H11+J11+L11+N11,IF($AD$2="JUNIO",F11+H11+J11+L11+N11+P11,IF($AD$2="JULIO",F11+H11+J11+L11+N11+P11+R11,IF($AD$2="AGOSTO",F11+H11+J11+L11+N11+P11+R11+T11,IF($AD$2="SEPTIEMBRE",F11+H11+J11+L11+N11+P11+R11+T11+V11,IF($AD$2="OCTUBRE",F11+H11+J11+L11+N11+P11+R11+T11+V11+X11,IF($AD$2="NOVIEMBRE",F11+H11+J11+L11+N11+P11+R11+T11+V11+X11+Z11,IF($AD$2="DICIEMBRE",F11+H11+J11+L11+N11+P11+R11+T11+V11+X11+Z11+AB11,"")))))))))))) -> 290 | AE11: =IFERROR(IF($AD$2="ENERO",G11,IF($AD$2="FEBRERO",G11+I11,IF($AD$2="MARZO",G11+I11+K11,IF($AD$2="ABRIL",G11+I11+K11+M11,IF($AD$2="MAYO",G11+I11+K11+M11+O11,IF($AD$2="JUNIO",G11+I11+K11+M11+O11+Q11,IF($AD$2="JULIO",G11+I11+K11+M11+O11+Q11+S11,IF($AD$2="AGOSTO",G11+I11+K11+M11+O11+Q11+S11+U11,IF($AD$2="SEPTIEMBRE",G11+I11+K11+M11+O11+Q11+S11+U11+W11,IF($AD$2="OCTUBRE",G11+I11+K11+M11+O11+Q11+S11+U11+W11+Y11,IF($AD$2="NOVIEMBRE",G11+I11+K11+M11+O11+Q11+S11+U11+W11+Y11+AA11,IF($AD$2="DICIEMBRE",G11+I11+K11+M11+O11+Q11+S11+U11+W11+Y11+AA11+AC11,"")))))))))))),0) -> 330 | AF11: =IFERROR((AE11/AD11),0) -> 1.137931 | AG11: =+F11+H11+J11+L11+N11+P11+R11+T11+V11+X11+Z11+AB11 -> 290 | AH11: =IFERROR(IF($AD$2="ENERO",G11,IF($AD$2="FEBRERO",G11+I11,IF($AD$2="MARZO",G11+I11+K11,IF($AD$2="ABRIL",G11+I11+K11+M11,IF($AD$2="MAYO",G11+I11+K11+M11+O11,IF($AD$2="JUNIO",G11+I11+K11+M11+O11+Q11,IF($AD$2="JULIO",G11+I11+K11+M11+O11+Q11+S11,IF($AD$2="AGOSTO",G11+I11+K11+M11+O11+Q11+S11+U11,IF($AD$2="SEPTIEMBRE",G11+I11+K11+M11+O11+Q11+S11+U11+W11,IF($AD$2="OCTUBRE",G11+I11+K11+M11+O11+Q11+S11+U11+W11+Y11,IF($AD$2="NOVIEMBRE",G11+I11+K11+M11+O11+Q11+S11+U11+W11+Y11+AA11,IF($AD$2="DICIEMBRE",G11+I11+K11+M11+O11+Q11+S11+U11+W11+Y11+AA11+AC11,"")))))))))))),0) -> 330 | AI11: =IFERROR((AH11/AG11),0) -> 1.137931 | AJ11: =IFERROR(IF($AJ$3="Q1",F11+H11+J11,IF($AJ$3="Q2",L11+N11++P11,IF($AJ$3="Q3",R11+T11+V11,IF($AJ$3="Q4",X11+Z11+AB11,0)))),0) -> 145 | AK11: =IFERROR(IF($AJ$3="Q1",G11+I11+K11,IF($AJ$3="Q2",M11+O11++Q11,IF($AJ$3="Q3",S11+U11+W11,IF($AJ$3="Q4",Y11+AA11+AC11,0)))),0) -> 170 | AL11: =IFERROR((AK11/AJ11),0) -> 1.1724138 | AM11: =IFERROR(IF($AM$3="S 1",F11+H11+J11+L11+N11++P11,IF($AM$3="S 2",R11+T11+V11+X11+Z11+AB11,0)),0) -> 0 | AN11: =IFERROR(IF($AM$3="S 1",G11+I11+K11+M11+O11+Q11,IF($AM$3="S 2",S11+U11+W11+Y11+AA11+AC11,0)),0) -> 0 | AO11: =IFERROR((AN11/AM11),0) -> 0
A12: 2 | B12: 100349 | C12: AUTO PREMIER | D12: 7450 | E12: Grupo Momentum | F12: 41 | G12: =IFERROR(VLOOKUP(B12,[2]RETAIL!$B$8:$O$63,3,0),0)-IFERROR(IF(B12=100873,VLOOKUP("ENERO",[2]RETAIL!$B$78:$C$91,2,0),0),0) -> 36 | H12: 41 | I12: =IFERROR(VLOOKUP(B12,[2]RETAIL!$B$8:$O$63,4,0),0)-IFERROR(IF(B12=100873,VLOOKUP("FEBRERO",[2]RETAIL!$B$78:$C$91,2,0),0),0) -> 60 | J12: 43 | K12: =IFERROR(VLOOKUP(B12,[2]RETAIL!$B$8:$O$63,5,0),0)-IFERROR(IF(B12=100873,VLOOKUP("MARZO",[2]RETAIL!$B$78:$C$91,2,0),0),0) -> 67 | L12: 41 | M12: =IFERROR(VLOOKUP(B12,[2]RETAIL!$B$8:$O$63,6,0),0)-IFERROR(IF(B12=100873,VLOOKUP("ABRIL",[2]RETAIL!$B$78:$C$91,2,0),0),0) -> 71 | N12: 41 | O12: =IFERROR(VLOOKUP(B12,[2]RETAIL!$B$8:$O$63,7,0),0)-IFERROR(IF(B12=100873,VLOOKUP("MAYO",[2]RETAIL!$B$78:$C$91,2,0),0),0) -> 44 | P12: 43 | Q12: =IFERROR(VLOOKUP(B12,[2]RETAIL!$B$8:$O$63,8,0),0)-IFERROR(IF(B12=100873,VLOOKUP("JUNIO",[2]RETAIL!$B$78:$C$91,2,0),0),0) -> 60 | S12: =IFERROR(VLOOKUP(B12,[2]RETAIL!$B$8:$O$63,9,0),0)-IFERROR(IF(B12=100873,VLOOKUP("JULIO",[2]RETAIL!$B$78:$C$91,2,0),0),0) -> 0 | U12: =IFERROR(VLOOKUP(B12,[2]RETAIL!$B$8:$O$63,10,0),0)-IFERROR(IF(B12=100873,VLOOKUP("AGOSTO",[2]RETAIL!$B$78:$C$91,2,0),0),0) -> 0 | W12: =IFERROR(VLOOKUP(B12,[2]RETAIL!$B$8:$O$63,11,0),0)-IFERROR(IF(B12=100873,VLOOKUP("SEPTIEMBRE",[2]RETAIL!$B$78:$C$91,2,0),0),0) -> 0 | Y12: =IFERROR(VLOOKUP(B12,[2]RETAIL!$B$8:$O$63,12,0),0)-IFERROR(IF(B12=100873,VLOOKUP("OCTUBRE",[2]RETAIL!$B$78:$C$91,2,0),0),0) -> 0 | AA12: =IFERROR(VLOOKUP(B12,[2]RETAIL!$B$8:$O$63,13,0),0)-IFERROR(IF(B12=100873,VLOOKUP("NOVIEMBRE",[2]RETAIL!$B$78:$C$91,2,0),0),0) -> 0 | AC12: =IFERROR(VLOOKUP(B12,[2]RETAIL!$B$8:$O$63,14,0),0)-IFERROR(IF(B12=100873,VLOOKUP("DICIEMBRE",[2]RETAIL!$B$78:$C$91,2,0),0),0) -> 0 | AD12: =IF($AD$2="ENERO",F12,IF($AD$2="FEBRERO",F12+H12,IF($AD$2="MARZO",F12+H12+J12,IF($AD$2="ABRIL",F12+H12+J12+L12,IF($AD$2="MAYO",F12+H12+J12+L12+N12,IF($AD$2="JUNIO",F12+H12+J12+L12+N12+P12,IF($AD$2="JULIO",F12+H12+J12+L12+N12+P12+R12,IF($AD$2="AGOSTO",F12+H12+J12+L12+N12+P12+R12+T12,IF($AD$2="SEPTIEMBRE",F12+H12+J12+L12+N12+P12+R12+T12+V12,IF($AD$2="OCTUBRE",F12+H12+J12+L12+N12+P12+R12+T12+V12+X12,IF($AD$2="NOVIEMBRE",F12+H12+J12+L12+N12+P12+R12+T12+V12+X12+Z12,IF($AD$2="DICIEMBRE",F12+H12+J12+L12+N12+P12+R12+T12+V12+X12+Z12+AB12,"")))))))))))) -> 250 | AE12: =IFERROR(IF($AD$2="ENERO",G12,IF($AD$2="FEBRERO",G12+I12,IF($AD$2="MARZO",G12+I12+K12,IF($AD$2="ABRIL",G12+I12+K12+M12,IF($AD$2="MAYO",G12+I12+K12+M12+O12,IF($AD$2="JUNIO",G12+I12+K12+M12+O12+Q12,IF($AD$2="JULIO",G12+I12+K12+M12+O12+Q12+S12,IF($AD$2="AGOSTO",G12+I12+K12+M12+O12+Q12+S12+U12,IF($AD$2="SEPTIEMBRE",G12+I12+K12+M12+O12+Q12+S12+U12+W12,IF($AD$2="OCTUBRE",G12+I12+K12+M12+O12+Q12+S12+U12+W12+Y12,IF($AD$2="NOVIEMBRE",G12+I12+K12+M12+O12+Q12+S12+U12+W12+Y12+AA12,IF($AD$2="DICIEMBRE",G12+I12+K12+M12+O12+Q12+S12+U12+W12+Y12+AA12+AC12,"")))))))))))),0) -> 338 | AF12: =IFERROR((AE12/AD12),0) -> 1.352 | AG12: =+F12+H12+J12+L12+N12+P12+R12+T12+V12+X12+Z12+AB12 -> 250 | AH12: =IFERROR(IF($AD$2="ENERO",G12,IF($AD$2="FEBRERO",G12+I12,IF($AD$2="MARZO",G12+I12+K12,IF($AD$2="ABRIL",G12+I12+K12+M12,IF($AD$2="MAYO",G12+I12+K12+M12+O12,IF($AD$2="JUNIO",G12+I12+K12+M12+O12+Q12,IF($AD$2="JULIO",G12+I12+K12+M12+O12+Q12+S12,IF($AD$2="AGOSTO",G12+I12+K12+M12+O12+Q12+S12+U12,IF($AD$2="SEPTIEMBRE",G12+I12+K12+M12+O12+Q12+S12+U12+W12,IF($AD$2="OCTUBRE",G12+I12+K12+M12+O12+Q12+S12+U12+W12+Y12,IF($AD$2="NOVIEMBRE",G12+I12+K12+M12+O12+Q12+S12+U12+W12+Y12+AA12,IF($AD$2="DICIEMBRE",G12+I12+K12+M12+O12+Q12+S12+U12+W12+Y12+AA12+AC12,"")))))))))))),0) -> 338 | AI12: =IFERROR((AH12/AG12),0) -> 1.352 | AJ12: =IFERROR(IF($AJ$3="Q1",F12+H12+J12,IF($AJ$3="Q2",L12+N12++P12,IF($AJ$3="Q3",R12+T12+V12,IF($AJ$3="Q4",X12+Z12+AB12,0)))),0) -> 125 | AK12: =IFERROR(IF($AJ$3="Q1",G12+I12+K12,IF($AJ$3="Q2",M12+O12++Q12,IF($AJ$3="Q3",S12+U12+W12,IF($AJ$3="Q4",Y12+AA12+AC12,0)))),0) -> 163 | AL12: =IFERROR((AK12/AJ12),0) -> 1.304 | AM12: =IFERROR(IF($AM$3="S 1",F12+H12+J12+L12+N12++P12,IF($AM$3="S 2",R12+T12+V12+X12+Z12+AB12,0)),0) -> 0 | AN12: =IFERROR(IF($AM$3="S 1",G12+I12+K12+M12+O12+Q12,IF($AM$3="S 2",S12+U12+W12+Y12+AA12+AC12,0)),0) -> 0 | AO12: =IFERROR((AN12/AM12),0) -> 0
A13: 2 | B13: 100917 | C13: MOMENTUM NORTE | D13: 7450 | E13: Grupo Momentum | F13: 1 | G13: =IFERROR(VLOOKUP(B13,[2]RETAIL!$B$8:$O$63,3,0),0)-IFERROR(IF(B13=100873,VLOOKUP("ENERO",[2]RETAIL!$B$78:$C$91,2,0),0),0) -> 0 | H13: 1 | I13: =IFERROR(VLOOKUP(B13,[2]RETAIL!$B$8:$O$63,4,0),0)-IFERROR(IF(B13=100873,VLOOKUP("FEBRERO",[2]RETAIL!$B$78:$C$91,2,0),0),0) -> 0 | J13: 18 | K13: =IFERROR(VLOOKUP(B13,[2]RETAIL!$B$8:$O$63,5,0),0)-IFERROR(IF(B13=100873,VLOOKUP("MARZO",[2]RETAIL!$B$78:$C$91,2,0),0),0) -> 0 | L13: 20 | M13: =IFERROR(VLOOKUP(B13,[2]RETAIL!$B$8:$O$63,6,0),0)-IFERROR(IF(B13=100873,VLOOKUP("ABRIL",[2]RETAIL!$B$78:$C$91,2,0),0),0) -> 7 | N13: 30 | O13: =IFERROR(VLOOKUP(B13,[2]RETAIL!$B$8:$O$63,7,0),0)-IFERROR(IF(B13=100873,VLOOKUP("MAYO",[2]RETAIL!$B$78:$C$91,2,0),0),0) -> 14 | P13: 30 | Q13: =IFERROR(VLOOKUP(B13,[2]RETAIL!$B$8:$O$63,8,0),0)-IFERROR(IF(B13=100873,VLOOKUP("JUNIO",[2]RETAIL!$B$78:$C$91,2,0),0),0) -> 27 | S13: =IFERROR(VLOOKUP(B13,[2]RETAIL!$B$8:$O$63,9,0),0)-IFERROR(IF(B13=100873,VLOOKUP("JULIO",[2]RETAIL!$B$78:$C$91,2,0),0),0) -> 0 | U13: =IFERROR(VLOOKUP(B13,[2]RETAIL!$B$8:$O$63,10,0),0)-IFERROR(IF(B13=100873,VLOOKUP("AGOSTO",[2]RETAIL!$B$78:$C$91,2,0),0),0) -> 0 | W13: =IFERROR(VLOOKUP(B13,[2]RETAIL!$B$8:$O$63,11,0),0)-IFERROR(IF(B13=100873,VLOOKUP("SEPTIEMBRE",[2]RETAIL!$B$78:$C$91,2,0),0),0) -> 0 | Y13: =IFERROR(VLOOKUP(B13,[2]RETAIL!$B$8:$O$63,12,0),0)-IFERROR(IF(B13=100873,VLOOKUP("OCTUBRE",[2]RETAIL!$B$78:$C$91,2,0),0),0) -> 0 | AA13: =IFERROR(VLOOKUP(B13,[2]RETAIL!$B$8:$O$63,13,0),0)-IFERROR(IF(B13=100873,VLOOKUP("NOVIEMBRE",[2]RETAIL!$B$78:$C$91,2,0),0),0) -> 0 | AC13: =IFERROR(VLOOKUP(B13,[2]RETAIL!$B$8:$O$63,14,0),0)-IFERROR(IF(B13=100873,VLOOKUP("DICIEMBRE",[2]RETAIL!$B$78:$C$91,2,0),0),0) -> 0 | AD13: =IF($AD$2="ENERO",F13,IF($AD$2="FEBRERO",F13+H13,IF($AD$2="MARZO",F13+H13+J13,IF($AD$2="ABRIL",F13+H13+J13+L13,IF($AD$2="MAYO",F13+H13+J13+L13+N13,IF($AD$2="JUNIO",F13+H13+J13+L13+N13+P13,IF($AD$2="JULIO",F13+H13+J13+L13+N13+P13+R13,IF($AD$2="AGOSTO",F13+H13+J13+L13+N13+P13+R13+T13,IF($AD$2="SEPTIEMBRE",F13+H13+J13+L13+N13+P13+R13+T13+V13,IF($AD$2="OCTUBRE",F13+H13+J13+L13+N13+P13+R13+T13+V13+X13,IF($AD$2="NOVIEMBRE",F13+H13+J13+L13+N13+P13+R13+T13+V13+X13+Z13,IF($AD$2="DICIEMBRE",F13+H13+J13+L13+N13+P13+R13+T13+V13+X13+Z13+AB13,"")))))))))))) -> 100 | AE13: =IFERROR(IF($AD$2="ENERO",G13,IF($AD$2="FEBRERO",G13+I13,IF($AD$2="MARZO",G13+I13+K13,IF($AD$2="ABRIL",G13+I13+K13+M13,IF($AD$2="MAYO",G13+I13+K13+M13+O13,IF($AD$2="JUNIO",G13+I13+K13+M13+O13+Q13,IF($AD$2="JULIO",G13+I13+K13+M13+O13+Q13+S13,IF($AD$2="AGOSTO",G13+I13+K13+M13+O13+Q13+S13+U13,IF($AD$2="SEPTIEMBRE",G13+I13+K13+M13+O13+Q13+S13+U13+W13,IF($AD$2="OCTUBRE",G13+I13+K13+M13+O13+Q13+S13+U13+W13+Y13,IF($AD$2="NOVIEMBRE",G13+I13+K13+M13+O13+Q13+S13+U13+W13+Y13+AA13,IF($AD$2="DICIEMBRE",G13+I13+K13+M13+O13+Q13+S13+U13+W13+Y13+AA13+AC13,"")))))))))))),0) -> 48 | AF13: =IFERROR((AE13/AD13),0) -> 0.48 | AG13: =+F13+H13+J13+L13+N13+P13+R13+T13+V13+X13+Z13+AB13 -> 100 | AH13: =IFERROR(IF($AD$2="ENERO",G13,IF($AD$2="FEBRERO",G13+I13,IF($AD$2="MARZO",G13+I13+K13,IF($AD$2="ABRIL",G13+I13+K13+M13,IF($AD$2="MAYO",G13+I13+K13+M13+O13,IF($AD$2="JUNIO",G13+I13+K13+M13+O13+Q13,IF($AD$2="JULIO",G13+I13+K13+M13+O13+Q13+S13,IF($AD$2="AGOSTO",G13+I13+K13+M13+O13+Q13+S13+U13,IF($AD$2="SEPTIEMBRE",G13+I13+K13+M13+O13+Q13+S13+U13+W13,IF($AD$2="OCTUBRE",G13+I13+K13+M13+O13+Q13+S13+U13+W13+Y13,IF($AD$2="NOVIEMBRE",G13+I13+K13+M13+O13+Q13+S13+U13+W13+Y13+AA13,IF($AD$2="DICIEMBRE",G13+I13+K13+M13+O13+Q13+S13+U13+W13+Y13+AA13+AC13,"")))))))))))),0) -> 48 | AI13: =IFERROR((AH13/AG13),0) -> 0.48 | AJ13: =IFERROR(IF($AJ$3="Q1",F13+H13+J13,IF($AJ$3="Q2",L13+N13++P13,IF($AJ$3="Q3",R13+T13+V13,IF($AJ$3="Q4",X13+Z13+AB13,0)))),0) -> 20 | AK13: =IFERROR(IF($AJ$3="Q1",G13+I13+K13,IF($AJ$3="Q2",M13+O13++Q13,IF($AJ$3="Q3",S13+U13+W13,IF($AJ$3="Q4",Y13+AA13+AC13,0)))),0) -> 0 | AL13: =IFERROR((AK13/AJ13),0) -> 0 | AM13: =IFERROR(IF($AM$3="S 1",F13+H13+J13+L13+N13++P13,IF($AM$3="S 2",R13+T13+V13+X13+Z13+AB13,0)),0) -> 0 | AN13: =IFERROR(IF($AM$3="S 1",G13+I13+K13+M13+O13+Q13,IF($AM$3="S 2",S13+U13+W13+Y13+AA13+AC13,0)),0) -> 0 | AO13: =IFERROR((AN13/AM13),0) -> 0
